Workbook

Sheet TỔNG THÁNG 08
A1: TỔNG THÁNG 08 | D1: SỐ CHUYẾN THEO CHỦ HÀNG | U1: TRẠNG THÁI | Z1: ĐÁNH GIÁ
A2: STT | B2: Biển số | C2: TỔNG | D2: Khai Anh | E2: Kim Bàng | F2: Vưu Đức Phát | G2: Phương Trang | H2: Lúa Vàng | I2: Hồng Nga | J2: Thuận An | K2: SIM | L2: THẢO AN | M2: Emivest | N2: LTP | O2: RICO | P2: Nhất Thành | Q2: Hoàng Mạnh Thắng | R2: TRANSIN | S2: HDVL | U2: TRỐNG LỊCH | V2: CHUYỂN ĐIỂM | W2: RỚT NHÀ MÁY | X2: TÀI XẾ NGHỈ | Z2: Ngày chạy | AA2: % HĐ | AB2: Hạng
B3: TỔNG | C3: =SUM(D3:S3) -> 629 | D3: =SUM(D5:D30) -> 348 | E3: =SUM(E5:E30) -> 7 | F3: =SUM(F5:F30) -> 28 | G3: =SUM(G5:G30) -> 5 | H3: =SUM(H5:H30) -> 10 | I3: =SUM(I5:I30) -> 0 | J3: =SUM(J5:J30) -> 50 | K3: =SUM(K5:K30) -> 0 | ... S3: =SUM(S5:S30) -> 55 | U3: =SUM(U5:U30) -> 13 | V3: =SUM(V5:V30) -> 7 | W3: =SUM(W5:W30) -> 18 | X3: =SUM(X5:X30) -> 60 | Z3: =SUM(Z5:Z30) -> 570
A5: 1 | B5: 63H04273 | C5: =SUM(D5:S5) -> 24 | D5: =COUNTIF($AN5:$EB5,D$2) -> 12 | E5: =COUNTIF($AN5:$EB5,E$2) -> 0 | F5: =COUNTIF($AN5:$EB5,F$2) -> 2 | G5: =COUNTIF($AN5:$EB5,G$2) -> 0 | H5: =COUNTIF($AN5:$EB5,H$2) -> 2 | I5: =COUNTIF($AN5:$EB5,I$2) -> 0 | J5: =COUNTIF($AN5:$EB5,J$2) -> 2 | K5: =COUNTIF($AN5:$EB5,K$2) -> 0 | ... S5: =COUNTIF($AN5:$EB5,S$2) -> 4 | U5: =COUNTIF($AN5:$EB5,U$2) -> 0 | V5: =COUNTIF($AN5:$EB5,V$2) -> 1 | W5: =COUNTIF($AN5:$EB5,W$2) -> 1 | X5: =COUNTIF($AN5:$EB5,X$2) -> 0 | Z5: ='01 - T7'!$N$3+'02 - CN'!$N$3+'03 - T2'!$N$3+'04 - T3'!$N$3+'05 - T4'!$N$3+'06 - T5'!$N$3+'07 - T6'!$N$3+'08 - T7'!$N$3+'09 - CN'!$N$3+'10 - T2'!$N$3+'11 - T3'!$N$3+'12 - T4'!$N$3+'13 - T5'!$N$3+'14 - T6'!$N$3+'15 - T7'!$N$3+'16 - CN'!$N$3+'17 - T2'!$N$3+'18 - T3'!$N$3+'19 - T4'!$N$3+'20 - T5'!$N$3+'21 - T6'!$N$3+'22 - T7'!$N$3+'23 - CN'!$N$3+'24 - T2'!$N$3+'25 - T3'!$N$3+'26 - T4'!$N$3+'27 - T5'!$N$3+'28 - T6'!$N$3+'29 - T7'!$N$3+'30 - CN'!$N$3+'31 - T2'!$N$3 -> 22 | AA5: =IF(B5="","",Z5/31) -> 0.70967742 | AB5: =IF(B5="","",RANK(C5,$C$5:$C$30,0)) -> 17 | AN5: ='01 - T7'!$E$3 -> HDVL | AO5: ='01 - T7'!$G$3 | AP5: ='01 - T7'!$I$3 | AQ5: ='02 - CN'!$E$3 | AR5: ='02 - CN'!$G$3 | AS5: ='02 - CN'!$I$3 | AT5: ='03 - T2'!$E$3 -> Lúa Vàng | AU5: ='03 - T2'!$G$3 | AV5: ='03 - T2'!$I$3 | AW5: ='04 - T3'!$E$3 -> Hoàng Mạnh Thắng | AX5: ='04 - T3'!$G$3 -> HDVL | AY5: ='04 - T3'!$I$3 | AZ5: ='05 - T4'!$E$3 | BA5: ='05 - T4'!$G$3 | BB5: ='05 - T4'!$I$3 | BC5: ='06 - T5'!$E$3 -> HDVL | BD5: ='06 - T5'!$G$3 | BE5: ='06 - T5'!$I$3 | BF5: ='07 - T6'!$E$3 -> Khai Anh | BG5: ='07 - T6'!$G$3 | BH5: ='07 - T6'!$I$3 | BI5: ='08 - T7'!$E$3 -> HDVL | BJ5: ='08 - T7'!$G$3 | BK5: ='08 - T7'!$I$3 | BL5: ='09 - CN'!$E$3 -> Khai Anh | BM5: ='09 - CN'!$G$3 | BN5: ='09 - CN'!$I$3 | BO5: ='10 - T2'!$E$3 -> CHUYỂN ĐIỂM | BP5: ='10 - T2'!$G$3 | BQ5: ='10 - T2'!$I$3 | BR5: ='11 - T3'!$E$3 -> Khai Anh | BS5: ='11 - T3'!$G$3 | BT5: ='11 - T3'!$I$3 | BU5: ='12 - T4'!$E$3 | BV5: ='12 - T4'!$G$3 | BW5: ='12 - T4'!$I$3 | BX5: ='13 - T5'!$E$3 -> Khai Anh | BY5: ='13 - T5'!$G$3 | BZ5: ='13 - T5'!$I$3 | CA5: ='14 - T6'!$E$3 -> Khai Anh | CB5: ='14 - T6'!$G$3 | CC5: ='14 - T6'!$I$3 | CD5: ='15 - T7'!$E$3 | CE5: ='15 - T7'!$G$3 | CF5: ='15 - T7'!$I$3 | CG5: ='16 - CN'!$E$3 -> Khai Anh | CH5: ='16 - CN'!$G$3 | CI5: ='16 - CN'!$I$3 | CJ5: ='17 - T2'!$E$3 -> Lúa Vàng | CK5: ='17 - T2'!$G$3 | CL5: ='17 - T2'!$I$3 | CM5: ='18 - T3'!$E$3 -> Khai Anh | CN5: ='18 - T3'!$G$3 | CO5: ='18 - T3'!$I$3 | CP5: ='19 - T4'!$E$3 -> Khai Anh | CQ5: ='19 - T4'!$G$3 | CR5: ='19 - T4'!$I$3 | CS5: ='20 - T5'!$E$3 -> Khai Anh | CT5: ='20 - T5'!$G$3 | CU5: ='20 - T5'!$I$3 | CV5: ='21 - T6'!$E$3 -> Khai Anh | CW5: ='21 - T6'!$G$3 | CX5: ='21 - T6'!$I$3 | CY5: ='22 - T7'!$E$3 | CZ5: ='22 - T7'!$G$3 | DA5: ='22 - T7'!$I$3 | DB5: ='23 - CN'!$E$3 -> RỚT NHÀ MÁY | DC5: ='23 - CN'!$G$3 | DD5: ='23 - CN'!$I$3 | DE5: ='24 - T2'!$E$3 -> Vưu Đức Phát | DF5: ='24 - T2'!$G$3 | DG5: ='24 - T2'!$I$3 | DH5: ='25 - T3'!$E$3 -> Khai Anh | DI5: ='25 - T3'!$G$3 | DJ5: ='25 - T3'!$I$3 | DK5: ='26 - T4'!$E$3 -> Thuận An | DL5: ='26 - T4'!$G$3 | DM5: ='26 - T4'!$I$3 | DN5: ='27 - T5'!$E$3 -> Hoàng Mạnh Thắng | DO5: ='27 - T5'!$G$3 -> Khai Anh | DP5: ='27 - T5'!$I$3 | DQ5: ='28 - T6'!$E$3 -> Vưu Đức Phát | DR5: ='28 - T6'!$G$3 | DS5: ='28 - T6'!$I$3 | DT5: ='29 - T7'!$E$3 -> Thuận An | DU5: ='29 - T7'!$G$3 | DV5: ='29 - T7'!$I$3 | DW5: ='30 - CN'!$E$3 | DX5: ='30 - CN'!$G$3 | DY5: ='30 - CN'!$I$3 | DZ5: ='31 - T2'!$E$3 | EA5: ='31 - T2'!$G$3 | EB5: ='31 - T2'!$I$3
A6: 2 | B6: 63G00286 | C6: =SUM(D6:S6) -> 32 | D6: =COUNTIF($AN6:$EB6,D$2) -> 17 | E6: =COUNTIF($AN6:$EB6,E$2) -> 0 | F6: =COUNTIF($AN6:$EB6,F$2) -> 0 | G6: =COUNTIF($AN6:$EB6,G$2) -> 0 | H6: =COUNTIF($AN6:$EB6,H$2) -> 0 | I6: =COUNTIF($AN6:$EB6,I$2) -> 0 | J6: =COUNTIF($AN6:$EB6,J$2) -> 3 | K6: =COUNTIF($AN6:$EB6,K$2) -> 0 | ... S6: =COUNTIF($AN6:$EB6,S$2) -> 0 | U6: =COUNTIF($AN6:$EB6,U$2) -> 0 | V6: =COUNTIF($AN6:$EB6,V$2) -> 0 | W6: =COUNTIF($AN6:$EB6,W$2) -> 3 | X6: =COUNTIF($AN6:$EB6,X$2) -> 0 | Z6: ='01 - T7'!$N$4+'02 - CN'!$N$4+'03 - T2'!$N$4+'04 - T3'!$N$4+'05 - T4'!$N$4+'06 - T5'!$N$4+'07 - T6'!$N$4+'08 - T7'!$N$4+'09 - CN'!$N$4+'10 - T2'!$N$4+'11 - T3'!$N$4+'12 - T4'!$N$4+'13 - T5'!$N$4+'14 - T6'!$N$4+'15 - T7'!$N$4+'16 - CN'!$N$4+'17 - T2'!$N$4+'18 - T3'!$N$4+'19 - T4'!$N$4+'20 - T5'!$N$4+'21 - T6'!$N$4+'22 - T7'!$N$4+'23 - CN'!$N$4+'24 - T2'!$N$4+'25 - T3'!$N$4+'26 - T4'!$N$4+'27 - T5'!$N$4+'28 - T6'!$N$4+'29 - T7'!$N$4+'30 - CN'!$N$4+'31 - T2'!$N$4 -> 24 | AA6: =IF(B6="","",Z6/31) -> 0.77419355 | AB6: =IF(B6="","",RANK(C6,$C$5:$C$30,0)) -> 1 | AN6: ='01 - T7'!$E$4 -> Hoàng Mạnh Thắng | AO6: ='01 - T7'!$G$4 | AP6: ='01 - T7'!$I$4 | AQ6: ='02 - CN'!$E$4 -> Hoàng Mạnh Thắng | AR6: ='02 - CN'!$G$4 -> Hoàng Mạnh Thắng | AS6: ='02 - CN'!$I$4 | AT6: ='03 - T2'!$E$4 -> Hoàng Mạnh Thắng | AU6: ='03 - T2'!$G$4 | AV6: ='03 - T2'!$I$4 | AW6: ='04 - T3'!$E$4 -> Hoàng Mạnh Thắng | AX6: ='04 - T3'!$G$4 | AY6: ='04 - T3'!$I$4 | AZ6: ='05 - T4'!$E$4 -> Khai Anh | BA6: ='05 - T4'!$G$4 | BB6: ='05 - T4'!$I$4 | BC6: ='06 - T5'!$E$4 -> Hoàng Mạnh Thắng | BD6: ='06 - T5'!$G$4 -> Hoàng Mạnh Thắng | BE6: ='06 - T5'!$I$4 | BF6: ='07 - T6'!$E$4 -> Hoàng Mạnh Thắng | BG6: ='07 - T6'!$G$4 -> Khai Anh | BH6: ='07 - T6'!$I$4 | BI6: ='08 - T7'!$E$4 -> RỚT NHÀ MÁY | BJ6: ='08 - T7'!$G$4 | BK6: ='08 - T7'!$I$4 | BL6: ='09 - CN'!$E$4 -> RỚT NHÀ MÁY | BM6: ='09 - CN'!$G$4 | BN6: ='09 - CN'!$I$4 | BO6: ='10 - T2'!$E$4 -> Hoàng Mạnh Thắng | BP6: ='10 - T2'!$G$4 -> Khai Anh | BQ6: ='10 - T2'!$I$4 | BR6: ='11 - T3'!$E$4 -> Khai Anh | BS6: ='11 - T3'!$G$4 | BT6: ='11 - T3'!$I$4 | BU6: ='12 - T4'!$E$4 -> RICO | BV6: ='12 - T4'!$G$4 -> Khai Anh | BW6: ='12 - T4'!$I$4 | BX6: ='13 - T5'!$E$4 -> Khai Anh | BY6: ='13 - T5'!$G$4 | BZ6: ='13 - T5'!$I$4 | CA6: ='14 - T6'!$E$4 -> Khai Anh | CB6: ='14 - T6'!$G$4 | CC6: ='14 - T6'!$I$4 | CD6: ='15 - T7'!$E$4 | CE6: ='15 - T7'!$G$4 | CF6: ='15 - T7'!$I$4 | CG6: ='16 - CN'!$E$4 -> Khai Anh | CH6: ='16 - CN'!$G$4 | CI6: ='16 - CN'!$I$4 | CJ6: ='17 - T2'!$E$4 -> Khai Anh | CK6: ='17 - T2'!$G$4 -> Thuận An | CL6: ='17 - T2'!$I$4 | CM6: ='18 - T3'!$E$4 -> Khai Anh | CN6: ='18 - T3'!$G$4 | CO6: ='18 - T3'!$I$4 | CP6: ='19 - T4'!$E$4 -> Khai Anh | CQ6: ='19 - T4'!$G$4 -> Khai Anh | CR6: ='19 - T4'!$I$4 | CS6: ='20 - T5'!$E$4 -> Khai Anh | CT6: ='20 - T5'!$G$4 | CU6: ='20 - T5'!$I$4 | CV6: ='21 - T6'!$E$4 -> Khai Anh | CW6: ='21 - T6'!$G$4 | CX6: ='21 - T6'!$I$4 | CY6: ='22 - T7'!$E$4 | CZ6: ='22 - T7'!$G$4 | DA6: ='22 - T7'!$I$4 | DB6: ='23 - CN'!$E$4 -> RỚT NHÀ MÁY | DC6: ='23 - CN'!$G$4 | DD6: ='23 - CN'!$I$4 | DE6: ='24 - T2'!$E$4 -> Khai Anh | DF6: ='24 - T2'!$G$4 | DG6: ='24 - T2'!$I$4 | DH6: ='25 - T3'!$E$4 -> Thuận An | DI6: ='25 - T3'!$G$4 | DJ6: ='25 - T3'!$I$4 | DK6: ='26 - T4'!$E$4 -> Khai Anh | DL6: ='26 - T4'!$G$4 | DM6: ='26 - T4'!$I$4 | DN6: ='27 - T5'!$E$4 -> Hoàng Mạnh Thắng | DO6: ='27 - T5'!$G$4 -> Khai Anh | DP6: ='27 - T5'!$I$4 | DQ6: ='28 - T6'!$E$4 -> Thuận An | DR6: ='28 - T6'!$G$4 | DS6: ='28 - T6'!$I$4 | DT6: ='29 - T7'!$E$4 -> LTP | DU6: ='29 - T7'!$G$4 | DV6: ='29 - T7'!$I$4 | DW6: ='30 - CN'!$E$4 | DX6: ='30 - CN'!$G$4 | DY6: ='30 - CN'!$I$4 | DZ6: ='31 - T2'!$E$4 | EA6: ='31 - T2'!$G$4 | EB6: ='31 - T2'!$I$4
A7: 3 | B7: 63E01156 | C7: =SUM(D7:S7) -> 31 | D7: =COUNTIF($AN7:$EB7,D$2) -> 19 | E7: =COUNTIF($AN7:$EB7,E$2) -> 0 | F7: =COUNTIF($AN7:$EB7,F$2) -> 0 | G7: =COUNTIF($AN7:$EB7,G$2) -> 0 | H7: =COUNTIF($AN7:$EB7,H$2) -> 1 | I7: =COUNTIF($AN7:$EB7,I$2) -> 0 | J7: =COUNTIF($AN7:$EB7,J$2) -> 2 | K7: =COUNTIF($AN7:$EB7,K$2) -> 0 | ... S7: =COUNTIF($AN7:$EB7,S$2) -> 2 | U7: =COUNTIF($AN7:$EB7,U$2) -> 0 | V7: =COUNTIF($AN7:$EB7,V$2) -> 0 | W7: =COUNTIF($AN7:$EB7,W$2) -> 0 | X7: =COUNTIF($AN7:$EB7,X$2) -> 0 | Z7: ='01 - T7'!$N$5+'02 - CN'!$N$5+'03 - T2'!$N$5+'04 - T3'!$N$5+'05 - T4'!$N$5+'06 - T5'!$N$5+'07 - T6'!$N$5+'08 - T7'!$N$5+'09 - CN'!$N$5+'10 - T2'!$N$5+'11 - T3'!$N$5+'12 - T4'!$N$5+'13 - T5'!$N$5+'14 - T6'!$N$5+'15 - T7'!$N$5+'16 - CN'!$N$5+'17 - T2'!$N$5+'18 - T3'!$N$5+'19 - T4'!$N$5+'20 - T5'!$N$5+'21 - T6'!$N$5+'22 - T7'!$N$5+'23 - CN'!$N$5+'24 - T2'!$N$5+'25 - T3'!$N$5+'26 - T4'!$N$5+'27 - T5'!$N$5+'28 - T6'!$N$5+'29 - T7'!$N$5+'30 - CN'!$N$5+'31 - T2'!$N$5 -> 27 | AA7: =IF(B7="","",Z7/31) -> 0.87096774 | AB7: =IF(B7="","",RANK(C7,$C$5:$C$30,0)) -> 2 | AN7: ='01 - T7'!$E$5 -> Khai Anh | AO7: ='01 - T7'!$G$5 | AP7: ='01 - T7'!$I$5 | AQ7: ='02 - CN'!$E$5 -> Khai Anh | AR7: ='02 - CN'!$G$5 | AS7: ='02 - CN'!$I$5 | AT7: ='03 - T2'!$E$5 -> Hoàng Mạnh Thắng | AU7: ='03 - T2'!$G$5 | AV7: ='03 - T2'!$I$5 | AW7: ='04 - T3'!$E$5 -> Hoàng Mạnh Thắng | AX7: ='04 - T3'!$G$5 -> Hoàng Mạnh Thắng | AY7: ='04 - T3'!$I$5 -> Khai Anh | AZ7: ='05 - T4'!$E$5 -> HDVL | BA7: ='05 - T4'!$G$5 | BB7: ='05 - T4'!$I$5 | BC7: ='06 - T5'!$E$5 -> Khai Anh | BD7: ='06 - T5'!$G$5 | BE7: ='06 - T5'!$I$5 | BF7: ='07 - T6'!$E$5 -> Hoàng Mạnh Thắng | BG7: ='07 - T6'!$G$5 -> Khai Anh | BH7: ='07 - T6'!$I$5 | BI7: ='08 - T7'!$E$5 -> Hoàng Mạnh Thắng | BJ7: ='08 - T7'!$G$5 | BK7: ='08 - T7'!$I$5 | BL7: ='09 - CN'!$E$5 -> Hoàng Mạnh Thắng | BM7: ='09 - CN'!$G$5 | BN7: ='09 - CN'!$I$5 | BO7: ='10 - T2'!$E$5 -> Khai Anh | BP7: ='10 - T2'!$G$5 | BQ7: ='10 - T2'!$I$5 | BR7: ='11 - T3'!$E$5 -> Khai Anh | BS7: ='11 - T3'!$G$5 | BT7: ='11 - T3'!$I$5 | BU7: ='12 - T4'!$E$5 -> Khai Anh | BV7: ='12 - T4'!$G$5 | BW7: ='12 - T4'!$I$5 | BX7: ='13 - T5'!$E$5 -> Khai Anh | BY7: ='13 - T5'!$G$5 | BZ7: ='13 - T5'!$I$5 | CA7: ='14 - T6'!$E$5 -> Khai Anh | CB7: ='14 - T6'!$G$5 | CC7: ='14 - T6'!$I$5 | CD7: ='15 - T7'!$E$5 | CE7: ='15 - T7'!$G$5 | CF7: ='15 - T7'!$I$5 | CG7: ='16 - CN'!$E$5 -> Khai Anh | CH7: ='16 - CN'!$G$5 | CI7: ='16 - CN'!$I$5 | CJ7: ='17 - T2'!$E$5 -> Khai Anh | CK7: ='17 - T2'!$G$5 | CL7: ='17 - T2'!$I$5 | CM7: ='18 - T3'!$E$5 -> Khai Anh | CN7: ='18 - T3'!$G$5 | CO7: ='18 - T3'!$I$5 | CP7: ='19 - T4'!$E$5 -> Khai Anh | CQ7: ='19 - T4'!$G$5 | CR7: ='19 - T4'!$I$5 | CS7: ='20 - T5'!$E$5 -> Khai Anh | CT7: ='20 - T5'!$G$5 | CU7: ='20 - T5'!$I$5 | CV7: ='21 - T6'!$E$5 -> Khai Anh | CW7: ='21 - T6'!$G$5 | CX7: ='21 - T6'!$I$5 | CY7: ='22 - T7'!$E$5 | CZ7: ='22 - T7'!$G$5 | DA7: ='22 - T7'!$I$5 | DB7: ='23 - CN'!$E$5 -> Thuận An | DC7: ='23 - CN'!$G$5 | DD7: ='23 - CN'!$I$5 | DE7: ='24 - T2'!$E$5 -> Khai Anh | DF7: ='24 - T2'!$G$5 | DG7: ='24 - T2'!$I$5 | DH7: ='25 - T3'!$E$5 -> Khai Anh | DI7: ='25 - T3'!$G$5 | DJ7: ='25 - T3'!$I$5 | DK7: ='26 - T4'!$E$5 -> Lúa Vàng | DL7: ='26 - T4'!$G$5 | DM7: ='26 - T4'!$I$5 | DN7: ='27 - T5'!$E$5 -> Hoàng Mạnh Thắng | DO7: ='27 - T5'!$G$5 -> Khai Anh | DP7: ='27 - T5'!$I$5 | DQ7: ='28 - T6'!$E$5 -> Thuận An | DR7: ='28 - T6'!$G$5 | DS7: ='28 - T6'!$I$5 | DT7: ='29 - T7'!$E$5 -> HDVL | DU7: ='29 - T7'!$G$5 | DV7: ='29 - T7'!$I$5 | DW7: ='30 - CN'!$E$5 | DX7: ='30 - CN'!$G$5 | DY7: ='30 - CN'!$I$5 | DZ7: ='31 - T2'!$E$5 | EA7: ='31 - T2'!$G$5 | EB7: ='31 - T2'!$I$5
A8: 4 | B8: 63E01117 | C8: =SUM(D8:S8) -> 17 | D8: =COUNTIF($AN8:$EB8,D$2) -> 8 | E8: =COUNTIF($AN8:$EB8,E$2) -> 0 | F8: =COUNTIF($AN8:$EB8,F$2) -> 0 | G8: =COUNTIF($AN8:$EB8,G$2) -> 0 | H8: =COUNTIF($AN8:$EB8,H$2) -> 0 | I8: =COUNTIF($AN8:$EB8,I$2) -> 0 | J8: =COUNTIF($AN8:$EB8,J$2) -> 0 | K8: =COUNTIF($AN8:$EB8,K$2) -> 0 | ... S8: =COUNTIF($AN8:$EB8,S$2) -> 1 | U8: =COUNTIF($AN8:$EB8,U$2) -> 0 | V8: =COUNTIF($AN8:$EB8,V$2) -> 0 | W8: =COUNTIF($AN8:$EB8,W$2) -> 0 | X8: =COUNTIF($AN8:$EB8,X$2) -> 14 | Z8: ='01 - T7'!$N$6+'02 - CN'!$N$6+'03 - T2'!$N$6+'04 - T3'!$N$6+'05 - T4'!$N$6+'06 - T5'!$N$6+'07 - T6'!$N$6+'08 - T7'!$N$6+'09 - CN'!$N$6+'10 - T2'!$N$6+'11 - T3'!$N$6+'12 - T4'!$N$6+'13 - T5'!$N$6+'14 - T6'!$N$6+'15 - T7'!$N$6+'16 - CN'!$N$6+'17 - T2'!$N$6+'18 - T3'!$N$6+'19 - T4'!$N$6+'20 - T5'!$N$6+'21 - T6'!$N$6+'22 - T7'!$N$6+'23 - CN'!$N$6+'24 - T2'!$N$6+'25 - T3'!$N$6+'26 - T4'!$N$6+'27 - T5'!$N$6+'28 - T6'!$N$6+'29 - T7'!$N$6+'30 - CN'!$N$6+'31 - T2'!$N$6 -> 14 | AA8: =IF(B8="","",Z8/31) -> 0.4516129 | AB8: =IF(B8="","",RANK(C8,$C$5:$C$30,0)) -> 24 | AN8: ='01 - T7'!$E$6 -> Hoàng Mạnh Thắng | AO8: ='01 - T7'!$G$6 | AP8: ='01 - T7'!$I$6 | AQ8: ='02 - CN'!$E$6 -> Hoàng Mạnh Thắng | AR8: ='02 - CN'!$G$6 -> Hoàng Mạnh Thắng | AS8: ='02 - CN'!$I$6 | AT8: ='03 - T2'!$E$6 -> Hoàng Mạnh Thắng | AU8: ='03 - T2'!$G$6 | AV8: ='03 - T2'!$I$6 | AW8: ='04 - T3'!$E$6 -> Hoàng Mạnh Thắng | AX8: ='04 - T3'!$G$6 -> Hoàng Mạnh Thắng | AY8: ='04 - T3'!$I$6 -> Khai Anh | AZ8: ='05 - T4'!$E$6 -> HDVL | BA8: ='05 - T4'!$G$6 | BB8: ='05 - T4'!$I$6 | BC8: ='06 - T5'!$E$6 -> Khai Anh | BD8: ='06 - T5'!$G$6 | BE8: ='06 - T5'!$I$6 | BF8: ='07 - T6'!$E$6 -> Hoàng Mạnh Thắng | BG8: ='07 - T6'!$G$6 | BH8: ='07 - T6'!$I$6 | BI8: ='08 - T7'!$E$6 -> Hoàng Mạnh Thắng | BJ8: ='08 - T7'!$G$6 | BK8: ='08 - T7'!$I$6 | BL8: ='09 - CN'!$E$6 -> Khai Anh | BM8: ='09 - CN'!$G$6 | BN8: ='09 - CN'!$I$6 | BO8: ='10 - T2'!$E$6 -> Khai Anh | BP8: ='10 - T2'!$G$6 | BQ8: ='10 - T2'!$I$6 | BR8: ='11 - T3'!$E$6 -> Khai Anh | BS8: ='11 - T3'!$G$6 | BT8: ='11 - T3'!$I$6 | BU8: ='12 - T4'!$E$6 | BV8: ='12 - T4'!$G$6 | BW8: ='12 - T4'!$I$6 | BX8: ='13 - T5'!$E$6 -> Khai Anh | BY8: ='13 - T5'!$G$6 | BZ8: ='13 - T5'!$I$6 | CA8: ='14 - T6'!$E$6 -> Khai Anh | CB8: ='14 - T6'!$G$6 | CC8: ='14 - T6'!$I$6 | CD8: ='15 - T7'!$E$6 -> Khai Anh | CE8: ='15 - T7'!$G$6 | CF8: ='15 - T7'!$I$6 | CG8: ='16 - CN'!$E$6 -> TÀI XẾ NGHỈ | CH8: ='16 - CN'!$G$6 | CI8: ='16 - CN'!$I$6 | CJ8: ='17 - T2'!$E$6 -> TÀI XẾ NGHỈ | CK8: ='17 - T2'!$G$6 | CL8: ='17 - T2'!$I$6 | CM8: ='18 - T3'!$E$6 -> TÀI XẾ NGHỈ | CN8: ='18 - T3'!$G$6 | CO8: ='18 - T3'!$I$6 | CP8: ='19 - T4'!$E$6 -> TÀI XẾ NGHỈ | CQ8: ='19 - T4'!$G$6 | CR8: ='19 - T4'!$I$6 | CS8: ='20 - T5'!$E$6 -> TÀI XẾ NGHỈ | CT8: ='20 - T5'!$G$6 | CU8: ='20 - T5'!$I$6 | CV8: ='21 - T6'!$E$6 -> TÀI XẾ NGHỈ | CW8: ='21 - T6'!$G$6 | CX8: ='21 - T6'!$I$6 | CY8: ='22 - T7'!$E$6 -> TÀI XẾ NGHỈ | CZ8: ='22 - T7'!$G$6 | DA8: ='22 - T7'!$I$6 | DB8: ='23 - CN'!$E$6 -> TÀI XẾ NGHỈ | DC8: ='23 - CN'!$G$6 | DD8: ='23 - CN'!$I$6 | DE8: ='24 - T2'!$E$6 -> TÀI XẾ NGHỈ | DF8: ='24 - T2'!$G$6 | DG8: ='24 - T2'!$I$6 | DH8: ='25 - T3'!$E$6 -> TÀI XẾ NGHỈ | DI8: ='25 - T3'!$G$6 | DJ8: ='25 - T3'!$I$6 | DK8: ='26 - T4'!$E$6 -> TÀI XẾ NGHỈ | DL8: ='26 - T4'!$G$6 | DM8: ='26 - T4'!$I$6 | DN8: ='27 - T5'!$E$6 -> TÀI XẾ NGHỈ | DO8: ='27 - T5'!$G$6 | DP8: ='27 - T5'!$I$6 | DQ8: ='28 - T6'!$E$6 -> TÀI XẾ NGHỈ | DR8: ='28 - T6'!$G$6 | DS8: ='28 - T6'!$I$6 | DT8: ='29 - T7'!$E$6 -> TÀI XẾ NGHỈ | DU8: ='29 - T7'!$G$6 | DV8: ='29 - T7'!$I$6 | DW8: ='30 - CN'!$E$6 | DX8: ='30 - CN'!$G$6 | DY8: ='30 - CN'!$I$6 | DZ8: ='31 - T2'!$E$6 | EA8: ='31 - T2'!$G$6 | EB8: ='31 - T2'!$I$6
A9: 5 | B9: 63E01108 | C9: =SUM(D9:S9) -> 30 | D9: =COUNTIF($AN9:$EB9,D$2) -> 13 | E9: =COUNTIF($AN9:$EB9,E$2) -> 0 | F9: =COUNTIF($AN9:$EB9,F$2) -> 0 | G9: =COUNTIF($AN9:$EB9,G$2) -> 0 | H9: =COUNTIF($AN9:$EB9,H$2) -> 0 | I9: =COUNTIF($AN9:$EB9,I$2) -> 0 | J9: =COUNTIF($AN9:$EB9,J$2) -> 7 | K9: =COUNTIF($AN9:$EB9,K$2) -> 0 | ... S9: =COUNTIF($AN9:$EB9,S$2) -> 0 | U9: =COUNTIF($AN9:$EB9,U$2) -> 0 | V9: =COUNTIF($AN9:$EB9,V$2) -> 0 | W9: =COUNTIF($AN9:$EB9,W$2) -> 0 | X9: =COUNTIF($AN9:$EB9,X$2) -> 3 | Z9: ='01 - T7'!$N$7+'02 - CN'!$N$7+'03 - T2'!$N$7+'04 - T3'!$N$7+'05 - T4'!$N$7+'06 - T5'!$N$7+'07 - T6'!$N$7+'08 - T7'!$N$7+'09 - CN'!$N$7+'10 - T2'!$N$7+'11 - T3'!$N$7+'12 - T4'!$N$7+'13 - T5'!$N$7+'14 - T6'!$N$7+'15 - T7'!$N$7+'16 - CN'!$N$7+'17 - T2'!$N$7+'18 - T3'!$N$7+'19 - T4'!$N$7+'20 - T5'!$N$7+'21 - T6'!$N$7+'22 - T7'!$N$7+'23 - CN'!$N$7+'24 - T2'!$N$7+'25 - T3'!$N$7+'26 - T4'!$N$7+'27 - T5'!$N$7+'28 - T6'!$N$7+'29 - T7'!$N$7+'30 - CN'!$N$7+'31 - T2'!$N$7 -> 23 | AA9: =IF(B9="","",Z9/31) -> 0.74193548 | AB9: =IF(B9="","",RANK(C9,$C$5:$C$30,0)) -> 3 | AN9: ='01 - T7'!$E$7 -> Hoàng Mạnh Thắng | AO9: ='01 - T7'!$G$7 | AP9: ='01 - T7'!$I$7 | AQ9: ='02 - CN'!$E$7 -> Hoàng Mạnh Thắng | AR9: ='02 - CN'!$G$7 -> Hoàng Mạnh Thắng | AS9: ='02 - CN'!$I$7 | AT9: ='03 - T2'!$E$7 -> Hoàng Mạnh Thắng | AU9: ='03 - T2'!$G$7 -> Thuận An | AV9: ='03 - T2'!$I$7 | AW9: ='04 - T3'!$E$7 -> Hoàng Mạnh Thắng | AX9: ='04 - T3'!$G$7 -> Thuận An | AY9: ='04 - T3'!$I$7 | AZ9: ='05 - T4'!$E$7 -> Hoàng Mạnh Thắng | BA9: ='05 - T4'!$G$7 | BB9: ='05 - T4'!$I$7 | BC9: ='06 - T5'!$E$7 -> Hoàng Mạnh Thắng | BD9: ='06 - T5'!$G$7 -> Thuận An | BE9: ='06 - T5'!$I$7 | BF9: ='07 - T6'!$E$7 -> Hoàng Mạnh Thắng | BG9: ='07 - T6'!$G$7 | BH9: ='07 - T6'!$I$7 | BI9: ='08 - T7'!$E$7 | BJ9: ='08 - T7'!$G$7 | BK9: ='08 - T7'!$I$7 | BL9: ='09 - CN'!$E$7 -> TÀI XẾ NGHỈ | BM9: ='09 - CN'!$G$7 | BN9: ='09 - CN'!$I$7 | BO9: ='10 - T2'!$E$7 -> TÀI XẾ NGHỈ | BP9: ='10 - T2'!$G$7 | BQ9: ='10 - T2'!$I$7 | BR9: ='11 - T3'!$E$7 -> TÀI XẾ NGHỈ | BS9: ='11 - T3'!$G$7 | BT9: ='11 - T3'!$I$7 | BU9: ='12 - T4'!$E$7 -> Khai Anh | BV9: ='12 - T4'!$G$7 | BW9: ='12 - T4'!$I$7 | BX9: ='13 - T5'!$E$7 -> Khai Anh | BY9: ='13 - T5'!$G$7 | BZ9: ='13 - T5'!$I$7 | CA9: ='14 - T6'!$E$7 -> Khai Anh | CB9: ='14 - T6'!$G$7 | CC9: ='14 - T6'!$I$7 | CD9: ='15 - T7'!$E$7 | CE9: ='15 - T7'!$G$7 | CF9: ='15 - T7'!$I$7 | CG9: ='16 - CN'!$E$7 -> Khai Anh | CH9: ='16 - CN'!$G$7 | CI9: ='16 - CN'!$I$7 | CJ9: ='17 - T2'!$E$7 -> Khai Anh | CK9: ='17 - T2'!$G$7 | CL9: ='17 - T2'!$I$7 | CM9: ='18 - T3'!$E$7 -> Khai Anh | CN9: ='18 - T3'!$G$7 -> Thuận An | CO9: ='18 - T3'!$I$7 | CP9: ='19 - T4'!$E$7 -> Khai Anh | CQ9: ='19 - T4'!$G$7 -> Thuận An | CR9: ='19 - T4'!$I$7 | CS9: ='20 - T5'!$E$7 -> Thuận An | CT9: ='20 - T5'!$G$7 | CU9: ='20 - T5'!$I$7 | CV9: ='21 - T6'!$E$7 -> Khai Anh | CW9: ='21 - T6'!$G$7 | CX9: ='21 - T6'!$I$7 | CY9: ='22 - T7'!$E$7 | CZ9: ='22 - T7'!$G$7 | DA9: ='22 - T7'!$I$7 | DB9: ='23 - CN'!$E$7 -> Khai Anh | DC9: ='23 - CN'!$G$7 | DD9: ='23 - CN'!$I$7 | DE9: ='24 - T2'!$E$7 -> Khai Anh | DF9: ='24 - T2'!$G$7 | DG9: ='24 - T2'!$I$7 | DH9: ='25 - T3'!$E$7 -> Khai Anh | DI9: ='25 - T3'!$G$7 | DJ9: ='25 - T3'!$I$7 | DK9: ='26 - T4'!$E$7 -> Khai Anh | DL9: ='26 - T4'!$G$7 | DM9: ='26 - T4'!$I$7 | DN9: ='27 - T5'!$E$7 -> Hoàng Mạnh Thắng | DO9: ='27 - T5'!$G$7 -> Khai Anh | DP9: ='27 - T5'!$I$7 | DQ9: ='28 - T6'!$E$7 -> Thuận An | DR9: ='28 - T6'!$G$7 | DS9: ='28 - T6'!$I$7 | DT9: ='29 - T7'!$E$7 -> LTP | DU9: ='29 - T7'!$G$7 | DV9: ='29 - T7'!$I$7 | DW9: ='30 - CN'!$E$7 | DX9: ='30 - CN'!$G$7 | DY9: ='30 - CN'!$I$7 | DZ9: ='31 - T2'!$E$7 | EA9: ='31 - T2'!$G$7 | EB9: ='31 - T2'!$I$7
A10: 6 | B10: 63F00528 | C10: =SUM(D10:S10) -> 17 | D10: =COUNTIF($AN10:$EB10,D$2) -> 11 | E10: =COUNTIF($AN10:$EB10,E$2) -> 1 | F10: =COUNTIF($AN10:$EB10,F$2) -> 2 | G10: =COUNTIF($AN10:$EB10,G$2) -> 0 | H10: =COUNTIF($AN10:$EB10,H$2) -> 0 | I10: =COUNTIF($AN10:$EB10,I$2) -> 0 | J10: =COUNTIF($AN10:$EB10,J$2) -> 0 | K10: =COUNTIF($AN10:$EB10,K$2) -> 0 | ... S10: =COUNTIF($AN10:$EB10,S$2) -> 1 | U10: =COUNTIF($AN10:$EB10,U$2) -> 1 | V10: =COUNTIF($AN10:$EB10,V$2) -> 1 | W10: =COUNTIF($AN10:$EB10,W$2) -> 2 | X10: =COUNTIF($AN10:$EB10,X$2) -> 5 | Z10: ='01 - T7'!$N$8+'02 - CN'!$N$8+'03 - T2'!$N$8+'04 - T3'!$N$8+'05 - T4'!$N$8+'06 - T5'!$N$8+'07 - T6'!$N$8+'08 - T7'!$N$8+'09 - CN'!$N$8+'10 - T2'!$N$8+'11 - T3'!$N$8+'12 - T4'!$N$8+'13 - T5'!$N$8+'14 - T6'!$N$8+'15 - T7'!$N$8+'16 - CN'!$N$8+'17 - T2'!$N$8+'18 - T3'!$N$8+'19 - T4'!$N$8+'20 - T5'!$N$8+'21 - T6'!$N$8+'22 - T7'!$N$8+'23 - CN'!$N$8+'24 - T2'!$N$8+'25 - T3'!$N$8+'26 - T4'!$N$8+'27 - T5'!$N$8+'28 - T6'!$N$8+'29 - T7'!$N$8+'30 - CN'!$N$8+'31 - T2'!$N$8 -> 17 | AA10: =IF(B10="","",Z10/31) -> 0.5483871 | AB10: =IF(B10="","",RANK(C10,$C$5:$C$30,0)) -> 24 | AN10: ='01 - T7'!$E$8 | AO10: ='01 - T7'!$G$8 | AP10: ='01 - T7'!$I$8 | AQ10: ='02 - CN'!$E$8 -> Khai Anh | AR10: ='02 - CN'!$G$8 | AS10: ='02 - CN'!$I$8 | AT10: ='03 - T2'!$E$8 -> Khai Anh | AU10: ='03 - T2'!$G$8 | AV10: ='03 - T2'!$I$8 | AW10: ='04 - T3'!$E$8 -> Khai Anh | AX10: ='04 - T3'!$G$8 | AY10: ='04 - T3'!$I$8 | AZ10: ='05 - T4'!$E$8 -> HDVL | BA10: ='05 - T4'!$G$8 | BB10: ='05 - T4'!$I$8 | BC10: ='06 - T5'!$E$8 -> TÀI XẾ NGHỈ | BD10: ='06 - T5'!$G$8 | BE10: ='06 - T5'!$I$8 | BF10: ='07 - T6'!$E$8 -> TÀI XẾ NGHỈ | BG10: ='07 - T6'!$G$8 | BH10: ='07 - T6'!$I$8 | BI10: ='08 - T7'!$E$8 -> TÀI XẾ NGHỈ | BJ10: ='08 - T7'!$G$8 | BK10: ='08 - T7'!$I$8 | BL10: ='09 - CN'!$E$8 -> TÀI XẾ NGHỈ | BM10: ='09 - CN'!$G$8 | BN10: ='09 - CN'!$I$8 | BO10: ='10 - T2'!$E$8 -> Khai Anh | BP10: ='10 - T2'!$G$8 | BQ10: ='10 - T2'!$I$8 | BR10: ='11 - T3'!$E$8 -> Khai Anh | BS10: ='11 - T3'!$G$8 | BT10: ='11 - T3'!$I$8 | BU10: ='12 - T4'!$E$8 -> CHUYỂN ĐIỂM | BV10: ='12 - T4'!$G$8 | BW10: ='12 - T4'!$I$8 | BX10: ='13 - T5'!$E$8 -> Emivest | BY10: ='13 - T5'!$G$8 | BZ10: ='13 - T5'!$I$8 | CA10: ='14 - T6'!$E$8 -> Emivest | CB10: ='14 - T6'!$G$8 | CC10: ='14 - T6'!$I$8 | CD10: ='15 - T7'!$E$8 | CE10: ='15 - T7'!$G$8 | CF10: ='15 - T7'!$I$8 | CG10: ='16 - CN'!$E$8 -> Khai Anh | CH10: ='16 - CN'!$G$8 | CI10: ='16 - CN'!$I$8 | CJ10: ='17 - T2'!$E$8 -> Khai Anh | CK10: ='17 - T2'!$G$8 | CL10: ='17 - T2'!$I$8 | CM10: ='18 - T3'!$E$8 -> Khai Anh | CN10: ='18 - T3'!$G$8 | CO10: ='18 - T3'!$I$8 | CP10: ='19 - T4'!$E$8 -> Khai Anh | CQ10: ='19 - T4'!$G$8 | CR10: ='19 - T4'!$I$8 | CS10: ='20 - T5'!$E$8 -> Khai Anh | CT10: ='20 - T5'!$G$8 | CU10: ='20 - T5'!$I$8 | CV10: ='21 - T6'!$E$8 -> RỚT NHÀ MÁY | CW10: ='21 - T6'!$G$8 | CX10: ='21 - T6'!$I$8 | CY10: ='22 - T7'!$E$8 -> Kim Bàng | CZ10: ='22 - T7'!$G$8 | DA10: ='22 - T7'!$I$8 | DB10: ='23 - CN'!$E$8 -> RỚT NHÀ MÁY | DC10: ='23 - CN'!$G$8 | DD10: ='23 - CN'!$I$8 | DE10: ='24 - T2'!$E$8 -> Vưu Đức Phát | DF10: ='24 - T2'!$G$8 | DG10: ='24 - T2'!$I$8 | DH10: ='25 - T3'!$E$8 -> TRỐNG LỊCH | DI10: ='25 - T3'!$G$8 | DJ10: ='25 - T3'!$I$8 | DK10: ='26 - T4'!$E$8 -> Khai Anh | DL10: ='26 - T4'!$G$8 | DM10: ='26 - T4'!$I$8 | DN10: ='27 - T5'!$E$8 | DO10: ='27 - T5'!$G$8 | DP10: ='27 - T5'!$I$8 | DQ10: ='28 - T6'!$E$8 -> Vưu Đức Phát | DR10: ='28 - T6'!$G$8 | DS10: ='28 - T6'!$I$8 | DT10: ='29 - T7'!$E$8 -> TÀI XẾ NGHỈ | DU10: ='29 - T7'!$G$8 | DV10: ='29 - T7'!$I$8 | DW10: ='30 - CN'!$E$8 | DX10: ='30 - CN'!$G$8 | DY10: ='30 - CN'!$I$8 | DZ10: ='31 - T2'!$E$8 | EA10: ='31 - T2'!$G$8 | EB10: ='31 - T2'!$I$8
A11: 7 | B11: 63G00262 | C11: =SUM(D11:S11) -> 20 | D11: =COUNTIF($AN11:$EB11,D$2) -> 11 | E11: =COUNTIF($AN11:$EB11,E$2) -> 0 | F11: =COUNTIF($AN11:$EB11,F$2) -> 0 | G11: =COUNTIF($AN11:$EB11,G$2) -> 0 | H11: =COUNTIF($AN11:$EB11,H$2) -> 0 | I11: =COUNTIF($AN11:$EB11,I$2) -> 0 | J11: =COUNTIF($AN11:$EB11,J$2) -> 4 | K11: =COUNTIF($AN11:$EB11,K$2) -> 0 | ... S11: =COUNTIF($AN11:$EB11,S$2) -> 1 | U11: =COUNTIF($AN11:$EB11,U$2) -> 2 | V11: =COUNTIF($AN11:$EB11,V$2) -> 0 | W11: =COUNTIF($AN11:$EB11,W$2) -> 0 | X11: =COUNTIF($AN11:$EB11,X$2) -> 5 | Z11: ='01 - T7'!$N$9+'02 - CN'!$N$9+'03 - T2'!$N$9+'04 - T3'!$N$9+'05 - T4'!$N$9+'06 - T5'!$N$9+'07 - T6'!$N$9+'08 - T7'!$N$9+'09 - CN'!$N$9+'10 - T2'!$N$9+'11 - T3'!$N$9+'12 - T4'!$N$9+'13 - T5'!$N$9+'14 - T6'!$N$9+'15 - T7'!$N$9+'16 - CN'!$N$9+'17 - T2'!$N$9+'18 - T3'!$N$9+'19 - T4'!$N$9+'20 - T5'!$N$9+'21 - T6'!$N$9+'22 - T7'!$N$9+'23 - CN'!$N$9+'24 - T2'!$N$9+'25 - T3'!$N$9+'26 - T4'!$N$9+'27 - T5'!$N$9+'28 - T6'!$N$9+'29 - T7'!$N$9+'30 - CN'!$N$9+'31 - T2'!$N$9 -> 18 | AA11: =IF(B11="","",Z11/31) -> 0.58064516 | AB11: =IF(B11="","",RANK(C11,$C$5:$C$30,0)) -> 21 | AN11: ='01 - T7'!$E$9 | AO11: ='01 - T7'!$G$9 | AP11: ='01 - T7'!$I$9 | AQ11: ='02 - CN'!$E$9 | AR11: ='02 - CN'!$G$9 | AS11: ='02 - CN'!$I$9 | AT11: ='03 - T2'!$E$9 -> TRỐNG LỊCH | AU11: ='03 - T2'!$G$9 | AV11: ='03 - T2'!$I$9 | AW11: ='04 - T3'!$E$9 -> TRỐNG LỊCH | AX11: ='04 - T3'!$G$9 | AY11: ='04 - T3'!$I$9 | AZ11: ='05 - T4'!$E$9 -> TÀI XẾ NGHỈ | BA11: ='05 - T4'!$G$9 | BB11: ='05 - T4'!$I$9 | BC11: ='06 - T5'!$E$9 -> HDVL | BD11: ='06 - T5'!$G$9 | BE11: ='06 - T5'!$I$9 | BF11: ='07 - T6'!$E$9 -> Hoàng Mạnh Thắng | BG11: ='07 - T6'!$G$9 | BH11: ='07 - T6'!$I$9 | BI11: ='08 - T7'!$E$9 | BJ11: ='08 - T7'!$G$9 | BK11: ='08 - T7'!$I$9 | BL11: ='09 - CN'!$E$9 -> TÀI XẾ NGHỈ | BM11: ='09 - CN'!$G$9 | BN11: ='09 - CN'!$I$9 | BO11: ='10 - T2'!$E$9 -> Hoàng Mạnh Thắng | BP11: ='10 - T2'!$G$9 -> Khai Anh | BQ11: ='10 - T2'!$I$9 | BR11: ='11 - T3'!$E$9 -> Thuận An | BS11: ='11 - T3'!$G$9 | BT11: ='11 - T3'!$I$9 | BU11: ='12 - T4'!$E$9 -> Khai Anh | BV11: ='12 - T4'!$G$9 | BW11: ='12 - T4'!$I$9 | BX11: ='13 - T5'!$E$9 -> Khai Anh | BY11: ='13 - T5'!$G$9 | BZ11: ='13 - T5'!$I$9 | CA11: ='14 - T6'!$E$9 -> Khai Anh | CB11: ='14 - T6'!$G$9 | CC11: ='14 - T6'!$I$9 | CD11: ='15 - T7'!$E$9 | CE11: ='15 - T7'!$G$9 | CF11: ='15 - T7'!$I$9 | CG11: ='16 - CN'!$E$9 -> Khai Anh | CH11: ='16 - CN'!$G$9 | CI11: ='16 - CN'!$I$9 | CJ11: ='17 - T2'!$E$9 -> Khai Anh | CK11: ='17 - T2'!$G$9 | CL11: ='17 - T2'!$I$9 | CM11: ='18 - T3'!$E$9 -> Khai Anh | CN11: ='18 - T3'!$G$9 | CO11: ='18 - T3'!$I$9 | CP11: ='19 - T4'!$E$9 -> RICO | CQ11: ='19 - T4'!$G$9 | CR11: ='19 - T4'!$I$9 | CS11: ='20 - T5'!$E$9 -> Khai Anh | CT11: ='20 - T5'!$G$9 | CU11: ='20 - T5'!$I$9 | CV11: ='21 - T6'!$E$9 -> Khai Anh | CW11: ='21 - T6'!$G$9 | CX11: ='21 - T6'!$I$9 | CY11: ='22 - T7'!$E$9 -> TÀI XẾ NGHỈ | CZ11: ='22 - T7'!$G$9 | DA11: ='22 - T7'!$I$9 | DB11: ='23 - CN'!$E$9 -> TÀI XẾ NGHỈ | DC11: ='23 - CN'!$G$9 | DD11: ='23 - CN'!$I$9 | DE11: ='24 - T2'!$E$9 -> Thuận An | DF11: ='24 - T2'!$G$9 | DG11: ='24 - T2'!$I$9 | DH11: ='25 - T3'!$E$9 -> Khai Anh | DI11: ='25 - T3'!$G$9 | DJ11: ='25 - T3'!$I$9 | DK11: ='26 - T4'!$E$9 -> Khai Anh | DL11: ='26 - T4'!$G$9 | DM11: ='26 - T4'!$I$9 | DN11: ='27 - T5'!$E$9 -> Hoàng Mạnh Thắng | DO11: ='27 - T5'!$G$9 -> Thuận An | DP11: ='27 - T5'!$I$9 | DQ11: ='28 - T6'!$E$9 -> Thuận An | DR11: ='28 - T6'!$G$9 | DS11: ='28 - T6'!$I$9 | DT11: ='29 - T7'!$E$9 -> TÀI XẾ NGHỈ | DU11: ='29 - T7'!$G$9 | DV11: ='29 - T7'!$I$9 | DW11: ='30 - CN'!$E$9 | DX11: ='30 - CN'!$G$9 | DY11: ='30 - CN'!$I$9 | DZ11: ='31 - T2'!$E$9 | EA11: ='31 - T2'!$G$9 | EB11: ='31 - T2'!$I$9
A12: 8 | B12: 63H04239 | C12: =SUM(D12:S12) -> 21 | D12: =COUNTIF($AN12:$EB12,D$2) -> 11 | E12: =COUNTIF($AN12:$EB12,E$2) -> 0 | F12: =COUNTIF($AN12:$EB12,F$2) -> 3 | G12: =COUNTIF($AN12:$EB12,G$2) -> 0 | H12: =COUNTIF($AN12:$EB12,H$2) -> 0 | I12: =COUNTIF($AN12:$EB12,I$2) -> 0 | J12: =COUNTIF($AN12:$EB12,J$2) -> 3 | K12: =COUNTIF($AN12:$EB12,K$2) -> 0 | ... S12: =COUNTIF($AN12:$EB12,S$2) -> 2 | U12: =COUNTIF($AN12:$EB12,U$2) -> 0 | V12: =COUNTIF($AN12:$EB12,V$2) -> 1 | W12: =COUNTIF($AN12:$EB12,W$2) -> 0 | X12: =COUNTIF($AN12:$EB12,X$2) -> 4 | Z12: ='01 - T7'!$N$10+'02 - CN'!$N$10+'03 - T2'!$N$10+'04 - T3'!$N$10+'05 - T4'!$N$10+'06 - T5'!$N$10+'07 - T6'!$N$10+'08 - T7'!$N$10+'09 - CN'!$N$10+'10 - T2'!$N$10+'11 - T3'!$N$10+'12 - T4'!$N$10+'13 - T5'!$N$10+'14 - T6'!$N$10+'15 - T7'!$N$10+'16 - CN'!$N$10+'17 - T2'!$N$10+'18 - T3'!$N$10+'19 - T4'!$N$10+'20 - T5'!$N$10+'21 - T6'!$N$10+'22 - T7'!$N$10+'23 - CN'!$N$10+'24 - T2'!$N$10+'25 - T3'!$N$10+'26 - T4'!$N$10+'27 - T5'!$N$10+'28 - T6'!$N$10+'29 - T7'!$N$10+'30 - CN'!$N$10+'31 - T2'!$N$10 -> 21 | AA12: =IF(B12="","",Z12/31) -> 0.67741935 | AB12: =IF(B12="","",RANK(C12,$C$5:$C$30,0)) -> 19 | AN12: ='01 - T7'!$E$10 -> TÀI XẾ NGHỈ | AO12: ='01 - T7'!$G$10 | AP12: ='01 - T7'!$I$10 | AQ12: ='02 - CN'!$E$10 -> TÀI XẾ NGHỈ | AR12: ='02 - CN'!$G$10 | AS12: ='02 - CN'!$I$10 | AT12: ='03 - T2'!$E$10 -> TÀI XẾ NGHỈ | AU12: ='03 - T2'!$G$10 | AV12: ='03 - T2'!$I$10 | AW12: ='04 - T3'!$E$10 -> TÀI XẾ NGHỈ | AX12: ='04 - T3'!$G$10 | AY12: ='04 - T3'!$I$10 | AZ12: ='05 - T4'!$E$10 | BA12: ='05 - T4'!$G$10 | BB12: ='05 - T4'!$I$10 | BC12: ='06 - T5'!$E$10 -> HDVL | BD12: ='06 - T5'!$G$10 | BE12: ='06 - T5'!$I$10 | BF12: ='07 - T6'!$E$10 -> Khai Anh | BG12: ='07 - T6'!$G$10 | BH12: ='07 - T6'!$I$10 | BI12: ='08 - T7'!$E$10 -> HDVL | BJ12: ='08 - T7'!$G$10 | BK12: ='08 - T7'!$I$10 | BL12: ='09 - CN'!$E$10 -> Khai Anh | BM12: ='09 - CN'!$G$10 | BN12: ='09 - CN'!$I$10 | BO12: ='10 - T2'!$E$10 -> Khai Anh | BP12: ='10 - T2'!$G$10 | BQ12: ='10 - T2'!$I$10 | BR12: ='11 - T3'!$E$10 -> Khai Anh | BS12: ='11 - T3'!$G$10 | BT12: ='11 - T3'!$I$10 | BU12: ='12 - T4'!$E$10 -> Thuận An | BV12: ='12 - T4'!$G$10 | BW12: ='12 - T4'!$I$10 | BX12: ='13 - T5'!$E$10 -> Emivest | BY12: ='13 - T5'!$G$10 | BZ12: ='13 - T5'!$I$10 | CA12: ='14 - T6'!$E$10 -> Emivest | CB12: ='14 - T6'!$G$10 | CC12: ='14 - T6'!$I$10 | CD12: ='15 - T7'!$E$10 | CE12: ='15 - T7'!$G$10 | CF12: ='15 - T7'!$I$10 | CG12: ='16 - CN'!$E$10 -> Thuận An | CH12: ='16 - CN'!$G$10 | CI12: ='16 - CN'!$I$10 | CJ12: ='17 - T2'!$E$10 -> Khai Anh | CK12: ='17 - T2'!$G$10 | CL12: ='17 - T2'!$I$10 | CM12: ='18 - T3'!$E$10 -> Khai Anh | CN12: ='18 - T3'!$G$10 | CO12: ='18 - T3'!$I$10 | CP12: ='19 - T4'!$E$10 -> Khai Anh | CQ12: ='19 - T4'!$G$10 | CR12: ='19 - T4'!$I$10 | CS12: ='20 - T5'!$E$10 -> Khai Anh | CT12: ='20 - T5'!$G$10 | CU12: ='20 - T5'!$I$10 | CV12: ='21 - T6'!$E$10 -> Khai Anh | CW12: ='21 - T6'!$G$10 | CX12: ='21 - T6'!$I$10 | CY12: ='22 - T7'!$E$10 | CZ12: ='22 - T7'!$G$10 | DA12: ='22 - T7'!$I$10 | DB12: ='23 - CN'!$E$10 -> Khai Anh | DC12: ='23 - CN'!$G$10 | DD12: ='23 - CN'!$I$10 | DE12: ='24 - T2'!$E$10 -> Vưu Đức Phát | DF12: ='24 - T2'!$G$10 | DG12: ='24 - T2'!$I$10 | DH12: ='25 - T3'!$E$10 -> Vưu Đức Phát | DI12: ='25 - T3'!$G$10 | DJ12: ='25 - T3'!$I$10 | DK12: ='26 - T4'!$E$10 -> Khai Anh | DL12: ='26 - T4'!$G$10 | DM12: ='26 - T4'!$I$10 | DN12: ='27 - T5'!$E$10 -> CHUYỂN ĐIỂM | DO12: ='27 - T5'!$G$10 | DP12: ='27 - T5'!$I$10 | DQ12: ='28 - T6'!$E$10 -> Vưu Đức Phát | DR12: ='28 - T6'!$G$10 | DS12: ='28 - T6'!$I$10 | DT12: ='29 - T7'!$E$10 -> Thuận An | DU12: ='29 - T7'!$G$10 | DV12: ='29 - T7'!$I$10 | DW12: ='30 - CN'!$E$10 | DX12: ='30 - CN'!$G$10 | DY12: ='30 - CN'!$I$10 | DZ12: ='31 - T2'!$E$10 | EA12: ='31 - T2'!$G$10 | EB12: ='31 - T2'!$I$10
A13: 9 | B13: 63E01276 | C13: =SUM(D13:S13) -> 30 | D13: =COUNTIF($AN13:$EB13,D$2) -> 16 | E13: =COUNTIF($AN13:$EB13,E$2) -> 1 | F13: =COUNTIF($AN13:$EB13,F$2) -> 1 | G13: =COUNTIF($AN13:$EB13,G$2) -> 0 | H13: =COUNTIF($AN13:$EB13,H$2) -> 0 | I13: =COUNTIF($AN13:$EB13,I$2) -> 0 | J13: =COUNTIF($AN13:$EB13,J$2) -> 3 | K13: =COUNTIF($AN13:$EB13,K$2) -> 0 | ... S13: =COUNTIF($AN13:$EB13,S$2) -> 3 | U13: =COUNTIF($AN13:$EB13,U$2) -> 0 | V13: =COUNTIF($AN13:$EB13,V$2) -> 1 | W13: =COUNTIF($AN13:$EB13,W$2) -> 0 | X13: =COUNTIF($AN13:$EB13,X$2) -> 0 | Z13: ='01 - T7'!$N$11+'02 - CN'!$N$11+'03 - T2'!$N$11+'04 - T3'!$N$11+'05 - T4'!$N$11+'06 - T5'!$N$11+'07 - T6'!$N$11+'08 - T7'!$N$11+'09 - CN'!$N$11+'10 - T2'!$N$11+'11 - T3'!$N$11+'12 - T4'!$N$11+'13 - T5'!$N$11+'14 - T6'!$N$11+'15 - T7'!$N$11+'16 - CN'!$N$11+'17 - T2'!$N$11+'18 - T3'!$N$11+'19 - T4'!$N$11+'20 - T5'!$N$11+'21 - T6'!$N$11+'22 - T7'!$N$11+'23 - CN'!$N$11+'24 - T2'!$N$11+'25 - T3'!$N$11+'26 - T4'!$N$11+'27 - T5'!$N$11+'28 - T6'!$N$11+'29 - T7'!$N$11+'30 - CN'!$N$11+'31 - T2'!$N$11 -> 26 | AA13: =IF(B13="","",Z13/31) -> 0.83870968 | AB13: =IF(B13="","",RANK(C13,$C$5:$C$30,0)) -> 3 | AN13: ='01 - T7'!$E$11 -> Hoàng Mạnh Thắng | AO13: ='01 - T7'!$G$11 | AP13: ='01 - T7'!$I$11 | AQ13: ='02 - CN'!$E$11 -> Hoàng Mạnh Thắng | AR13: ='02 - CN'!$G$11 -> Khai Anh | AS13: ='02 - CN'!$I$11 | AT13: ='03 - T2'!$E$11 -> Khai Anh | AU13: ='03 - T2'!$G$11 | AV13: ='03 - T2'!$I$11 | AW13: ='04 - T3'!$E$11 -> Thuận An | AX13: ='04 - T3'!$G$11 | AY13: ='04 - T3'!$I$11 | AZ13: ='05 - T4'!$E$11 -> HDVL | BA13: ='05 - T4'!$G$11 -> HDVL | BB13: ='05 - T4'!$I$11 | BC13: ='06 - T5'!$E$11 -> Khai Anh | BD13: ='06 - T5'!$G$11 | BE13: ='06 - T5'!$I$11 | BF13: ='07 - T6'!$E$11 -> Hoàng Mạnh Thắng | BG13: ='07 - T6'!$G$11 | BH13: ='07 - T6'!$I$11 | BI13: ='08 - T7'!$E$11 -> Hoàng Mạnh Thắng | BJ13: ='08 - T7'!$G$11 -> HDVL | BK13: ='08 - T7'!$I$11 | BL13: ='09 - CN'!$E$11 -> Khai Anh | BM13: ='09 - CN'!$G$11 | BN13: ='09 - CN'!$I$11 | BO13: ='10 - T2'!$E$11 -> Khai Anh | BP13: ='10 - T2'!$G$11 | BQ13: ='10 - T2'!$I$11 | BR13: ='11 - T3'!$E$11 -> Khai Anh | BS13: ='11 - T3'!$G$11 | BT13: ='11 - T3'!$I$11 | BU13: ='12 - T4'!$E$11 -> Khai Anh | BV13: ='12 - T4'!$G$11 | BW13: ='12 - T4'!$I$11 | BX13: ='13 - T5'!$E$11 -> Emivest | BY13: ='13 - T5'!$G$11 | BZ13: ='13 - T5'!$I$11 | CA13: ='14 - T6'!$E$11 -> Emivest | CB13: ='14 - T6'!$G$11 -> Kim Bàng | CC13: ='14 - T6'!$I$11 | CD13: ='15 - T7'!$E$11 | CE13: ='15 - T7'!$G$11 | CF13: ='15 - T7'!$I$11 | CG13: ='16 - CN'!$E$11 -> Khai Anh | CH13: ='16 - CN'!$G$11 | CI13: ='16 - CN'!$I$11 | CJ13: ='17 - T2'!$E$11 -> Khai Anh | CK13: ='17 - T2'!$G$11 | CL13: ='17 - T2'!$I$11 | CM13: ='18 - T3'!$E$11 -> Thuận An | CN13: ='18 - T3'!$G$11 | CO13: ='18 - T3'!$I$11 | CP13: ='19 - T4'!$E$11 -> Khai Anh | CQ13: ='19 - T4'!$G$11 | CR13: ='19 - T4'!$I$11 | CS13: ='20 - T5'!$E$11 -> Khai Anh | CT13: ='20 - T5'!$G$11 | CU13: ='20 - T5'!$I$11 | CV13: ='21 - T6'!$E$11 -> Khai Anh | CW13: ='21 - T6'!$G$11 | CX13: ='21 - T6'!$I$11 | CY13: ='22 - T7'!$E$11 | CZ13: ='22 - T7'!$G$11 | DA13: ='22 - T7'!$I$11 | DB13: ='23 - CN'!$E$11 -> Khai Anh | DC13: ='23 - CN'!$G$11 | DD13: ='23 - CN'!$I$11 | DE13: ='24 - T2'!$E$11 -> Khai Anh | DF13: ='24 - T2'!$G$11 | DG13: ='24 - T2'!$I$11 | DH13: ='25 - T3'!$E$11 -> CHUYỂN ĐIỂM | DI13: ='25 - T3'!$G$11 | DJ13: ='25 - T3'!$I$11 | DK13: ='26 - T4'!$E$11 -> Khai Anh | DL13: ='26 - T4'!$G$11 | DM13: ='26 - T4'!$I$11 | DN13: ='27 - T5'!$E$11 -> Thuận An | DO13: ='27 - T5'!$G$11 | DP13: ='27 - T5'!$I$11 | DQ13: ='28 - T6'!$E$11 -> Vưu Đức Phát | DR13: ='28 - T6'!$G$11 | DS13: ='28 - T6'!$I$11 | DT13: ='29 - T7'!$E$11 -> Khai Anh | DU13: ='29 - T7'!$G$11 | DV13: ='29 - T7'!$I$11 | DW13: ='30 - CN'!$E$11 | DX13: ='30 - CN'!$G$11 | DY13: ='30 - CN'!$I$11 | DZ13: ='31 - T2'!$E$11 | EA13: ='31 - T2'!$G$11 | EB13: ='31 - T2'!$I$11
A14: 10 | B14: 63E01103 | C14: =SUM(D14:S14) -> 27 | D14: =COUNTIF($AN14:$EB14,D$2) -> 14 | E14: =COUNTIF($AN14:$EB14,E$2) -> 1 | F14: =COUNTIF($AN14:$EB14,F$2) -> 0 | G14: =COUNTIF($AN14:$EB14,G$2) -> 0 | H14: =COUNTIF($AN14:$EB14,H$2) -> 0 | I14: =COUNTIF($AN14:$EB14,I$2) -> 0 | J14: =COUNTIF($AN14:$EB14,J$2) -> 1 | K14: =COUNTIF($AN14:$EB14,K$2) -> 0 | ... S14: =COUNTIF($AN14:$EB14,S$2) -> 3 | U14: =COUNTIF($AN14:$EB14,U$2) -> 0 | V14: =COUNTIF($AN14:$EB14,V$2) -> 2 | W14: =COUNTIF($AN14:$EB14,W$2) -> 0 | X14: =COUNTIF($AN14:$EB14,X$2) -> 2 | Z14: ='01 - T7'!$N$12+'02 - CN'!$N$12+'03 - T2'!$N$12+'04 - T3'!$N$12+'05 - T4'!$N$12+'06 - T5'!$N$12+'07 - T6'!$N$12+'08 - T7'!$N$12+'09 - CN'!$N$12+'10 - T2'!$N$12+'11 - T3'!$N$12+'12 - T4'!$N$12+'13 - T5'!$N$12+'14 - T6'!$N$12+'15 - T7'!$N$12+'16 - CN'!$N$12+'17 - T2'!$N$12+'18 - T3'!$N$12+'19 - T4'!$N$12+'20 - T5'!$N$12+'21 - T6'!$N$12+'22 - T7'!$N$12+'23 - CN'!$N$12+'24 - T2'!$N$12+'25 - T3'!$N$12+'26 - T4'!$N$12+'27 - T5'!$N$12+'28 - T6'!$N$12+'29 - T7'!$N$12+'30 - CN'!$N$12+'31 - T2'!$N$12 -> 23 | AA14: =IF(B14="","",Z14/31) -> 0.74193548 | AB14: =IF(B14="","",RANK(C14,$C$5:$C$30,0)) -> 9 | AN14: ='01 - T7'!$E$12 -> Hoàng Mạnh Thắng | AO14: ='01 - T7'!$G$12 | AP14: ='01 - T7'!$I$12 | AQ14: ='02 - CN'!$E$12 -> Hoàng Mạnh Thắng | AR14: ='02 - CN'!$G$12 -> Hoàng Mạnh Thắng | AS14: ='02 - CN'!$I$12 | AT14: ='03 - T2'!$E$12 -> Thuận An | AU14: ='03 - T2'!$G$12 -> Khai Anh | AV14: ='03 - T2'!$I$12 | AW14: ='04 - T3'!$E$12 | AX14: ='04 - T3'!$G$12 | AY14: ='04 - T3'!$I$12 | AZ14: ='05 - T4'!$E$12 -> Khai Anh | BA14: ='05 - T4'!$G$12 | BB14: ='05 - T4'!$I$12 | BC14: ='06 - T5'!$E$12 -> Khai Anh | BD14: ='06 - T5'!$G$12 | BE14: ='06 - T5'!$I$12 | BF14: ='07 - T6'!$E$12 -> HDVL | BG14: ='07 - T6'!$G$12 | BH14: ='07 - T6'!$I$12 | BI14: ='08 - T7'!$E$12 -> HDVL | BJ14: ='08 - T7'!$G$12 | BK14: ='08 - T7'!$I$12 | BL14: ='09 - CN'!$E$12 -> Emivest | BM14: ='09 - CN'!$G$12 | BN14: ='09 - CN'!$I$12 | BO14: ='10 - T2'!$E$12 -> Emivest | BP14: ='10 - T2'!$G$12 -> Emivest | BQ14: ='10 - T2'!$I$12 | BR14: ='11 - T3'!$E$12 -> Emivest | BS14: ='11 - T3'!$G$12 | BT14: ='11 - T3'!$I$12 | BU14: ='12 - T4'!$E$12 -> Khai Anh | BV14: ='12 - T4'!$G$12 | BW14: ='12 - T4'!$I$12 | BX14: ='13 - T5'!$E$12 -> Emivest | BY14: ='13 - T5'!$G$12 | BZ14: ='13 - T5'!$I$12 | CA14: ='14 - T6'!$E$12 -> Khai Anh | CB14: ='14 - T6'!$G$12 -> Kim Bàng | CC14: ='14 - T6'!$I$12 | CD14: ='15 - T7'!$E$12 | CE14: ='15 - T7'!$G$12 | CF14: ='15 - T7'!$I$12 | CG14: ='16 - CN'!$E$12 -> TÀI XẾ NGHỈ | CH14: ='16 - CN'!$G$12 | CI14: ='16 - CN'!$I$12 | CJ14: ='17 - T2'!$E$12 -> Khai Anh | CK14: ='17 - T2'!$G$12 | CL14: ='17 - T2'!$I$12 | CM14: ='18 - T3'!$E$12 -> CHUYỂN ĐIỂM | CN14: ='18 - T3'!$G$12 | CO14: ='18 - T3'!$I$12 | CP14: ='19 - T4'!$E$12 -> CHUYỂN ĐIỂM | CQ14: ='19 - T4'!$G$12 | CR14: ='19 - T4'!$I$12 | CS14: ='20 - T5'!$E$12 -> Khai Anh | CT14: ='20 - T5'!$G$12 | CU14: ='20 - T5'!$I$12 | CV14: ='21 - T6'!$E$12 -> Khai Anh | CW14: ='21 - T6'!$G$12 | CX14: ='21 - T6'!$I$12 | CY14: ='22 - T7'!$E$12 -> HDVL | CZ14: ='22 - T7'!$G$12 | DA14: ='22 - T7'!$I$12 | DB14: ='23 - CN'!$E$12 -> Khai Anh | DC14: ='23 - CN'!$G$12 | DD14: ='23 - CN'!$I$12 | DE14: ='24 - T2'!$E$12 -> Khai Anh | DF14: ='24 - T2'!$G$12 | DG14: ='24 - T2'!$I$12 | DH14: ='25 - T3'!$E$12 -> Khai Anh | DI14: ='25 - T3'!$G$12 | DJ14: ='25 - T3'!$I$12 | DK14: ='26 - T4'!$E$12 -> Khai Anh | DL14: ='26 - T4'!$G$12 | DM14: ='26 - T4'!$I$12 | DN14: ='27 - T5'!$E$12 -> Khai Anh | DO14: ='27 - T5'!$G$12 | DP14: ='27 - T5'!$I$12 | DQ14: ='28 - T6'!$E$12 -> Khai Anh | DR14: ='28 - T6'!$G$12 | DS14: ='28 - T6'!$I$12 | DT14: ='29 - T7'!$E$12 -> TÀI XẾ NGHỈ | DU14: ='29 - T7'!$G$12 | DV14: ='29 - T7'!$I$12 | DW14: ='30 - CN'!$E$12 | DX14: ='30 - CN'!$G$12 | DY14: ='30 - CN'!$I$12 | DZ14: ='31 - T2'!$E$12 | EA14: ='31 - T2'!$G$12 | EB14: ='31 - T2'!$I$12
A15: 11 | B15: 63E01118 | C15: =SUM(D15:S15) -> 28 | D15: =COUNTIF($AN15:$EB15,D$2) -> 15 | E15: =COUNTIF($AN15:$EB15,E$2) -> 0 | F15: =COUNTIF($AN15:$EB15,F$2) -> 1 | G15: =COUNTIF($AN15:$EB15,G$2) -> 0 | H15: =COUNTIF($AN15:$EB15,H$2) -> 0 | I15: =COUNTIF($AN15:$EB15,I$2) -> 0 | J15: =COUNTIF($AN15:$EB15,J$2) -> 3 | K15: =COUNTIF($AN15:$EB15,K$2) -> 0 | ... S15: =COUNTIF($AN15:$EB15,S$2) -> 4 | U15: =COUNTIF($AN15:$EB15,U$2) -> 0 | V15: =COUNTIF($AN15:$EB15,V$2) -> 0 | W15: =COUNTIF($AN15:$EB15,W$2) -> 0 | X15: =COUNTIF($AN15:$EB15,X$2) -> 0 | Z15: ='01 - T7'!$N$13+'02 - CN'!$N$13+'03 - T2'!$N$13+'04 - T3'!$N$13+'05 - T4'!$N$13+'06 - T5'!$N$13+'07 - T6'!$N$13+'08 - T7'!$N$13+'09 - CN'!$N$13+'10 - T2'!$N$13+'11 - T3'!$N$13+'12 - T4'!$N$13+'13 - T5'!$N$13+'14 - T6'!$N$13+'15 - T7'!$N$13+'16 - CN'!$N$13+'17 - T2'!$N$13+'18 - T3'!$N$13+'19 - T4'!$N$13+'20 - T5'!$N$13+'21 - T6'!$N$13+'22 - T7'!$N$13+'23 - CN'!$N$13+'24 - T2'!$N$13+'25 - T3'!$N$13+'26 - T4'!$N$13+'27 - T5'!$N$13+'28 - T6'!$N$13+'29 - T7'!$N$13+'30 - CN'!$N$13+'31 - T2'!$N$13 -> 26 | AA15: =IF(B15="","",Z15/31) -> 0.83870968 | AB15: =IF(B15="","",RANK(C15,$C$5:$C$30,0)) -> 8 | AN15: ='01 - T7'!$E$13 -> Hoàng Mạnh Thắng | AO15: ='01 - T7'!$G$13 -> HDVL | AP15: ='01 - T7'!$I$13 | AQ15: ='02 - CN'!$E$13 -> Khai Anh | AR15: ='02 - CN'!$G$13 | AS15: ='02 - CN'!$I$13 | AT15: ='03 - T2'!$E$13 -> Hoàng Mạnh Thắng | AU15: ='03 - T2'!$G$13 | AV15: ='03 - T2'!$I$13 | AW15: ='04 - T3'!$E$13 -> Hoàng Mạnh Thắng | AX15: ='04 - T3'!$G$13 -> Khai Anh | AY15: ='04 - T3'!$I$13 | AZ15: ='05 - T4'!$E$13 -> Thuận An | BA15: ='05 - T4'!$G$13 | BB15: ='05 - T4'!$I$13 | BC15: ='06 - T5'!$E$13 -> Khai Anh | BD15: ='06 - T5'!$G$13 | BE15: ='06 - T5'!$I$13 | BF15: ='07 - T6'!$E$13 -> HDVL | BG15: ='07 - T6'!$G$13 | BH15: ='07 - T6'!$I$13 | BI15: ='08 - T7'!$E$13 -> HDVL | BJ15: ='08 - T7'!$G$13 | BK15: ='08 - T7'!$I$13 | BL15: ='09 - CN'!$E$13 | BM15: ='09 - CN'!$G$13 | BN15: ='09 - CN'!$I$13 | BO15: ='10 - T2'!$E$13 -> Khai Anh | BP15: ='10 - T2'!$G$13 | BQ15: ='10 - T2'!$I$13 | BR15: ='11 - T3'!$E$13 -> Thuận An | BS15: ='11 - T3'!$G$13 | BT15: ='11 - T3'!$I$13 | BU15: ='12 - T4'!$E$13 -> Thuận An | BV15: ='12 - T4'!$G$13 | BW15: ='12 - T4'!$I$13 | BX15: ='13 - T5'!$E$13 -> Emivest | BY15: ='13 - T5'!$G$13 | BZ15: ='13 - T5'!$I$13 | CA15: ='14 - T6'!$E$13 -> Emivest | CB15: ='14 - T6'!$G$13 | CC15: ='14 - T6'!$I$13 | CD15: ='15 - T7'!$E$13 | CE15: ='15 - T7'!$G$13 | CF15: ='15 - T7'!$I$13 | CG15: ='16 - CN'!$E$13 -> Khai Anh | CH15: ='16 - CN'!$G$13 | CI15: ='16 - CN'!$I$13 | CJ15: ='17 - T2'!$E$13 -> Khai Anh | CK15: ='17 - T2'!$G$13 | CL15: ='17 - T2'!$I$13 | CM15: ='18 - T3'!$E$13 -> Khai Anh | CN15: ='18 - T3'!$G$13 | CO15: ='18 - T3'!$I$13 | CP15: ='19 - T4'!$E$13 -> Khai Anh | CQ15: ='19 - T4'!$G$13 | CR15: ='19 - T4'!$I$13 | CS15: ='20 - T5'!$E$13 -> Khai Anh | CT15: ='20 - T5'!$G$13 | CU15: ='20 - T5'!$I$13 | CV15: ='21 - T6'!$E$13 -> Khai Anh | CW15: ='21 - T6'!$G$13 | CX15: ='21 - T6'!$I$13 | CY15: ='22 - T7'!$E$13 | CZ15: ='22 - T7'!$G$13 | DA15: ='22 - T7'!$I$13 | DB15: ='23 - CN'!$E$13 -> Khai Anh | DC15: ='23 - CN'!$G$13 | DD15: ='23 - CN'!$I$13 | DE15: ='24 - T2'!$E$13 -> Khai Anh | DF15: ='24 - T2'!$G$13 | DG15: ='24 - T2'!$I$13 | DH15: ='25 - T3'!$E$13 -> Khai Anh | DI15: ='25 - T3'!$G$13 | DJ15: ='25 - T3'!$I$13 | DK15: ='26 - T4'!$E$13 -> Khai Anh | DL15: ='26 - T4'!$G$13 | DM15: ='26 - T4'!$I$13 | DN15: ='27 - T5'!$E$13 -> Khai Anh | DO15: ='27 - T5'!$G$13 | DP15: ='27 - T5'!$I$13 | DQ15: ='28 - T6'!$E$13 -> Vưu Đức Phát | DR15: ='28 - T6'!$G$13 | DS15: ='28 - T6'!$I$13 | DT15: ='29 - T7'!$E$13 -> HDVL | DU15: ='29 - T7'!$G$13 | DV15: ='29 - T7'!$I$13 | DW15: ='30 - CN'!$E$13 | DX15: ='30 - CN'!$G$13 | DY15: ='30 - CN'!$I$13 | DZ15: ='31 - T2'!$E$13 | EA15: ='31 - T2'!$G$13 | EB15: ='31 - T2'!$I$13
A16: 12 | B16: 63F00511 | C16: =SUM(D16:S16) -> 30 | D16: =COUNTIF($AN16:$EB16,D$2) -> 13 | E16: =COUNTIF($AN16:$EB16,E$2) -> 0 | F16: =COUNTIF($AN16:$EB16,F$2) -> 0 | G16: =COUNTIF($AN16:$EB16,G$2) -> 0 | H16: =COUNTIF($AN16:$EB16,H$2) -> 2 | I16: =COUNTIF($AN16:$EB16,I$2) -> 0 | J16: =COUNTIF($AN16:$EB16,J$2) -> 4 | K16: =COUNTIF($AN16:$EB16,K$2) -> 0 | ... S16: =COUNTIF($AN16:$EB16,S$2) -> 1 | U16: =COUNTIF($AN16:$EB16,U$2) -> 0 | V16: =COUNTIF($AN16:$EB16,V$2) -> 0 | W16: =COUNTIF($AN16:$EB16,W$2) -> 0 | X16: =COUNTIF($AN16:$EB16,X$2) -> 2 | Z16: ='01 - T7'!$N$14+'02 - CN'!$N$14+'03 - T2'!$N$14+'04 - T3'!$N$14+'05 - T4'!$N$14+'06 - T5'!$N$14+'07 - T6'!$N$14+'08 - T7'!$N$14+'09 - CN'!$N$14+'10 - T2'!$N$14+'11 - T3'!$N$14+'12 - T4'!$N$14+'13 - T5'!$N$14+'14 - T6'!$N$14+'15 - T7'!$N$14+'16 - CN'!$N$14+'17 - T2'!$N$14+'18 - T3'!$N$14+'19 - T4'!$N$14+'20 - T5'!$N$14+'21 - T6'!$N$14+'22 - T7'!$N$14+'23 - CN'!$N$14+'24 - T2'!$N$14+'25 - T3'!$N$14+'26 - T4'!$N$14+'27 - T5'!$N$14+'28 - T6'!$N$14+'29 - T7'!$N$14+'30 - CN'!$N$14+'31 - T2'!$N$14 -> 26 | AA16: =IF(B16="","",Z16/31) -> 0.83870968 | AB16: =IF(B16="","",RANK(C16,$C$5:$C$30,0)) -> 3 | AN16: ='01 - T7'!$E$14 -> Hoàng Mạnh Thắng | AO16: ='01 - T7'!$G$14 | AP16: ='01 - T7'!$I$14 | AQ16: ='02 - CN'!$E$14 -> Hoàng Mạnh Thắng | AR16: ='02 - CN'!$G$14 -> Khai Anh | AS16: ='02 - CN'!$I$14 | AT16: ='03 - T2'!$E$14 -> Hoàng Mạnh Thắng | AU16: ='03 - T2'!$G$14 | AV16: ='03 - T2'!$I$14 | AW16: ='04 - T3'!$E$14 -> Hoàng Mạnh Thắng | AX16: ='04 - T3'!$G$14 -> Khai Anh | AY16: ='04 - T3'!$I$14 | AZ16: ='05 - T4'!$E$14 -> Khai Anh | BA16: ='05 - T4'!$G$14 | BB16: ='05 - T4'!$I$14 | BC16: ='06 - T5'!$E$14 -> HDVL | BD16: ='06 - T5'!$G$14 | BE16: ='06 - T5'!$I$14 | BF16: ='07 - T6'!$E$14 -> Hoàng Mạnh Thắng | BG16: ='07 - T6'!$G$14 | BH16: ='07 - T6'!$I$14 | BI16: ='08 - T7'!$E$14 -> Hoàng Mạnh Thắng | BJ16: ='08 - T7'!$G$14 | BK16: ='08 - T7'!$I$14 | BL16: ='09 - CN'!$E$14 -> Hoàng Mạnh Thắng | BM16: ='09 - CN'!$G$14 | BN16: ='09 - CN'!$I$14 | BO16: ='10 - T2'!$E$14 -> Hoàng Mạnh Thắng | BP16: ='10 - T2'!$G$14 -> Thuận An | BQ16: ='10 - T2'!$I$14 | BR16: ='11 - T3'!$E$14 -> Khai Anh | BS16: ='11 - T3'!$G$14 | BT16: ='11 - T3'!$I$14 | BU16: ='12 - T4'!$E$14 -> Thuận An | BV16: ='12 - T4'!$G$14 | BW16: ='12 - T4'!$I$14 | BX16: ='13 - T5'!$E$14 -> Khai Anh | BY16: ='13 - T5'!$G$14 | BZ16: ='13 - T5'!$I$14 | CA16: ='14 - T6'!$E$14 -> Khai Anh | CB16: ='14 - T6'!$G$14 | CC16: ='14 - T6'!$I$14 | CD16: ='15 - T7'!$E$14 | CE16: ='15 - T7'!$G$14 | CF16: ='15 - T7'!$I$14 | CG16: ='16 - CN'!$E$14 -> Khai Anh | CH16: ='16 - CN'!$G$14 | CI16: ='16 - CN'!$I$14 | CJ16: ='17 - T2'!$E$14 -> Khai Anh | CK16: ='17 - T2'!$G$14 | CL16: ='17 - T2'!$I$14 | CM16: ='18 - T3'!$E$14 -> Khai Anh | CN16: ='18 - T3'!$G$14 | CO16: ='18 - T3'!$I$14 | CP16: ='19 - T4'!$E$14 -> Lúa Vàng | CQ16: ='19 - T4'!$G$14 | CR16: ='19 - T4'!$I$14 | CS16: ='20 - T5'!$E$14 -> Khai Anh | CT16: ='20 - T5'!$G$14 | CU16: ='20 - T5'!$I$14 | CV16: ='21 - T6'!$E$14 -> TÀI XẾ NGHỈ | CW16: ='21 - T6'!$G$14 | CX16: ='21 - T6'!$I$14 | CY16: ='22 - T7'!$E$14 -> TÀI XẾ NGHỈ | CZ16: ='22 - T7'!$G$14 | DA16: ='22 - T7'!$I$14 | DB16: ='23 - CN'!$E$14 -> Khai Anh | DC16: ='23 - CN'!$G$14 | DD16: ='23 - CN'!$I$14 | DE16: ='24 - T2'!$E$14 -> Khai Anh | DF16: ='24 - T2'!$G$14 | DG16: ='24 - T2'!$I$14 | DH16: ='25 - T3'!$E$14 -> Lúa Vàng | DI16: ='25 - T3'!$G$14 | DJ16: ='25 - T3'!$I$14 | DK16: ='26 - T4'!$E$14 -> Thuận An | DL16: ='26 - T4'!$G$14 | DM16: ='26 - T4'!$I$14 | DN16: ='27 - T5'!$E$14 -> Hoàng Mạnh Thắng | DO16: ='27 - T5'!$G$14 -> Thuận An | DP16: ='27 - T5'!$I$14 | DQ16: ='28 - T6'!$E$14 -> Khai Anh | DR16: ='28 - T6'!$G$14 | DS16: ='28 - T6'!$I$14 | DT16: ='29 - T7'!$E$14 -> LTP | DU16: ='29 - T7'!$G$14 | DV16: ='29 - T7'!$I$14 | DW16: ='30 - CN'!$E$14 | DX16: ='30 - CN'!$G$14 | DY16: ='30 - CN'!$I$14 | DZ16: ='31 - T2'!$E$14 | EA16: ='31 - T2'!$G$14 | EB16: ='31 - T2'!$I$14
A17: 13 | B17: 63H04234 | C17: =SUM(D17:S17) -> 29 | D17: =COUNTIF($AN17:$EB17,D$2) -> 16 | E17: =COUNTIF($AN17:$EB17,E$2) -> 1 | F17: =COUNTIF($AN17:$EB17,F$2) -> 0 | G17: =COUNTIF($AN17:$EB17,G$2) -> 1 | H17: =COUNTIF($AN17:$EB17,H$2) -> 1 | I17: =COUNTIF($AN17:$EB17,I$2) -> 0 | J17: =COUNTIF($AN17:$EB17,J$2) -> 3 | K17: =COUNTIF($AN17:$EB17,K$2) -> 0 | ... S17: =COUNTIF($AN17:$EB17,S$2) -> 4 | U17: =COUNTIF($AN17:$EB17,U$2) -> 0 | V17: =COUNTIF($AN17:$EB17,V$2) -> 0 | W17: =COUNTIF($AN17:$EB17,W$2) -> 0 | X17: =COUNTIF($AN17:$EB17,X$2) -> 3 | Z17: ='01 - T7'!$N$15+'02 - CN'!$N$15+'03 - T2'!$N$15+'04 - T3'!$N$15+'05 - T4'!$N$15+'06 - T5'!$N$15+'07 - T6'!$N$15+'08 - T7'!$N$15+'09 - CN'!$N$15+'10 - T2'!$N$15+'11 - T3'!$N$15+'12 - T4'!$N$15+'13 - T5'!$N$15+'14 - T6'!$N$15+'15 - T7'!$N$15+'16 - CN'!$N$15+'17 - T2'!$N$15+'18 - T3'!$N$15+'19 - T4'!$N$15+'20 - T5'!$N$15+'21 - T6'!$N$15+'22 - T7'!$N$15+'23 - CN'!$N$15+'24 - T2'!$N$15+'25 - T3'!$N$15+'26 - T4'!$N$15+'27 - T5'!$N$15+'28 - T6'!$N$15+'29 - T7'!$N$15+'30 - CN'!$N$15+'31 - T2'!$N$15 -> 24 | AA17: =IF(B17="","",Z17/31) -> 0.77419355 | AB17: =IF(B17="","",RANK(C17,$C$5:$C$30,0)) -> 6 | AN17: ='01 - T7'!$E$15 -> Khai Anh | AO17: ='01 - T7'!$G$15 -> HDVL | AP17: ='01 - T7'!$I$15 | AQ17: ='02 - CN'!$E$15 -> Khai Anh | AR17: ='02 - CN'!$G$15 | AS17: ='02 - CN'!$I$15 | AT17: ='03 - T2'!$E$15 | AU17: ='03 - T2'!$G$15 | AV17: ='03 - T2'!$I$15 | AW17: ='04 - T3'!$E$15 -> Khai Anh | AX17: ='04 - T3'!$G$15 | AY17: ='04 - T3'!$I$15 | AZ17: ='05 - T4'!$E$15 -> HDVL | BA17: ='05 - T4'!$G$15 | BB17: ='05 - T4'!$I$15 | BC17: ='06 - T5'!$E$15 -> Khai Anh | BD17: ='06 - T5'!$G$15 | BE17: ='06 - T5'!$I$15 | BF17: ='07 - T6'!$E$15 -> Hoàng Mạnh Thắng | BG17: ='07 - T6'!$G$15 -> Khai Anh | BH17: ='07 - T6'!$I$15 | BI17: ='08 - T7'!$E$15 -> Hoàng Mạnh Thắng | BJ17: ='08 - T7'!$G$15 -> HDVL | BK17: ='08 - T7'!$I$15 | BL17: ='09 - CN'!$E$15 -> Khai Anh | BM17: ='09 - CN'!$G$15 | BN17: ='09 - CN'!$I$15 | BO17: ='10 - T2'!$E$15 -> Thuận An | BP17: ='10 - T2'!$G$15 | BQ17: ='10 - T2'!$I$15 | BR17: ='11 - T3'!$E$15 -> Khai Anh | BS17: ='11 - T3'!$G$15 | BT17: ='11 - T3'!$I$15 | BU17: ='12 - T4'!$E$15 -> Phương Trang | BV17: ='12 - T4'!$G$15 | BW17: ='12 - T4'!$I$15 | BX17: ='13 - T5'!$E$15 | BY17: ='13 - T5'!$G$15 | BZ17: ='13 - T5'!$I$15 | CA17: ='14 - T6'!$E$15 -> TÀI XẾ NGHỈ | CB17: ='14 - T6'!$G$15 | CC17: ='14 - T6'!$I$15 | CD17: ='15 - T7'!$E$15 -> TÀI XẾ NGHỈ | CE17: ='15 - T7'!$G$15 | CF17: ='15 - T7'!$I$15 | CG17: ='16 - CN'!$E$15 -> TÀI XẾ NGHỈ | CH17: ='16 - CN'!$G$15 | CI17: ='16 - CN'!$I$15 | CJ17: ='17 - T2'!$E$15 -> Khai Anh | CK17: ='17 - T2'!$G$15 | CL17: ='17 - T2'!$I$15 | CM17: ='18 - T3'!$E$15 -> Khai Anh | CN17: ='18 - T3'!$G$15 | CO17: ='18 - T3'!$I$15 | CP17: ='19 - T4'!$E$15 -> Khai Anh | CQ17: ='19 - T4'!$G$15 | CR17: ='19 - T4'!$I$15 | CS17: ='20 - T5'!$E$15 -> Khai Anh | CT17: ='20 - T5'!$G$15 | CU17: ='20 - T5'!$I$15 | CV17: ='21 - T6'!$E$15 -> Kim Bàng | CW17: ='21 - T6'!$G$15 -> Khai Anh | CX17: ='21 - T6'!$I$15 | CY17: ='22 - T7'!$E$15 -> HDVL | CZ17: ='22 - T7'!$G$15 | DA17: ='22 - T7'!$I$15 | DB17: ='23 - CN'!$E$15 -> Khai Anh | DC17: ='23 - CN'!$G$15 | DD17: ='23 - CN'!$I$15 | DE17: ='24 - T2'!$E$15 -> Lúa Vàng | DF17: ='24 - T2'!$G$15 | DG17: ='24 - T2'!$I$15 | DH17: ='25 - T3'!$E$15 -> Khai Anh | DI17: ='25 - T3'!$G$15 | DJ17: ='25 - T3'!$I$15 | DK17: ='26 - T4'!$E$15 -> Khai Anh | DL17: ='26 - T4'!$G$15 | DM17: ='26 - T4'!$I$15 | DN17: ='27 - T5'!$E$15 -> Hoàng Mạnh Thắng | DO17: ='27 - T5'!$G$15 -> Khai Anh | DP17: ='27 - T5'!$I$15 | DQ17: ='28 - T6'!$E$15 -> Thuận An | DR17: ='28 - T6'!$G$15 | DS17: ='28 - T6'!$I$15 | DT17: ='29 - T7'!$E$15 -> Thuận An | DU17: ='29 - T7'!$G$15 | DV17: ='29 - T7'!$I$15 | DW17: ='30 - CN'!$E$15 | DX17: ='30 - CN'!$G$15 | DY17: ='30 - CN'!$I$15 | DZ17: ='31 - T2'!$E$15 | EA17: ='31 - T2'!$G$15 | EB17: ='31 - T2'!$I$15
A18: 14 | B18: 63E01235 | C18: =SUM(D18:S18) -> 26 | D18: =COUNTIF($AN18:$EB18,D$2) -> 14 | E18: =COUNTIF($AN18:$EB18,E$2) -> 0 | F18: =COUNTIF($AN18:$EB18,F$2) -> 1 | G18: =COUNTIF($AN18:$EB18,G$2) -> 1 | H18: =COUNTIF($AN18:$EB18,H$2) -> 2 | I18: =COUNTIF($AN18:$EB18,I$2) -> 0 | J18: =COUNTIF($AN18:$EB18,J$2) -> 1 | K18: =COUNTIF($AN18:$EB18,K$2) -> 0 | ... S18: =COUNTIF($AN18:$EB18,S$2) -> 4 | U18: =COUNTIF($AN18:$EB18,U$2) -> 0 | V18: =COUNTIF($AN18:$EB18,V$2) -> 0 | W18: =COUNTIF($AN18:$EB18,W$2) -> 2 | X18: =COUNTIF($AN18:$EB18,X$2) -> 1 | Z18: ='01 - T7'!$N$16+'02 - CN'!$N$16+'03 - T2'!$N$16+'04 - T3'!$N$16+'05 - T4'!$N$16+'06 - T5'!$N$16+'07 - T6'!$N$16+'08 - T7'!$N$16+'09 - CN'!$N$16+'10 - T2'!$N$16+'11 - T3'!$N$16+'12 - T4'!$N$16+'13 - T5'!$N$16+'14 - T6'!$N$16+'15 - T7'!$N$16+'16 - CN'!$N$16+'17 - T2'!$N$16+'18 - T3'!$N$16+'19 - T4'!$N$16+'20 - T5'!$N$16+'21 - T6'!$N$16+'22 - T7'!$N$16+'23 - CN'!$N$16+'24 - T2'!$N$16+'25 - T3'!$N$16+'26 - T4'!$N$16+'27 - T5'!$N$16+'28 - T6'!$N$16+'29 - T7'!$N$16+'30 - CN'!$N$16+'31 - T2'!$N$16 -> 24 | AA18: =IF(B18="","",Z18/31) -> 0.77419355 | AB18: =IF(B18="","",RANK(C18,$C$5:$C$30,0)) -> 13 | AN18: ='01 - T7'!$E$16 -> HDVL | AO18: ='01 - T7'!$G$16 | AP18: ='01 - T7'!$I$16 | AQ18: ='02 - CN'!$E$16 -> Khai Anh | AR18: ='02 - CN'!$G$16 | AS18: ='02 - CN'!$I$16 | AT18: ='03 - T2'!$E$16 -> Hoàng Mạnh Thắng | AU18: ='03 - T2'!$G$16 | AV18: ='03 - T2'!$I$16 | AW18: ='04 - T3'!$E$16 -> Hoàng Mạnh Thắng | AX18: ='04 - T3'!$G$16 -> HDVL | AY18: ='04 - T3'!$I$16 | AZ18: ='05 - T4'!$E$16 | BA18: ='05 - T4'!$G$16 | BB18: ='05 - T4'!$I$16 | BC18: ='06 - T5'!$E$16 -> HDVL | BD18: ='06 - T5'!$G$16 | BE18: ='06 - T5'!$I$16 | BF18: ='07 - T6'!$E$16 -> Khai Anh | BG18: ='07 - T6'!$G$16 -> Hoàng Mạnh Thắng | BH18: ='07 - T6'!$I$16 | BI18: ='08 - T7'!$E$16 -> Khai Anh | BJ18: ='08 - T7'!$G$16 -> RỚT NHÀ MÁY | BK18: ='08 - T7'!$I$16 | BL18: ='09 - CN'!$E$16 -> RỚT NHÀ MÁY | BM18: ='09 - CN'!$G$16 | BN18: ='09 - CN'!$I$16 | BO18: ='10 - T2'!$E$16 -> Khai Anh | BP18: ='10 - T2'!$G$16 | BQ18: ='10 - T2'!$I$16 | BR18: ='11 - T3'!$E$16 | BS18: ='11 - T3'!$G$16 | BT18: ='11 - T3'!$I$16 | BU18: ='12 - T4'!$E$16 -> Lúa Vàng | BV18: ='12 - T4'!$G$16 | BW18: ='12 - T4'!$I$16 | BX18: ='13 - T5'!$E$16 -> Khai Anh | BY18: ='13 - T5'!$G$16 | BZ18: ='13 - T5'!$I$16 | CA18: ='14 - T6'!$E$16 -> Khai Anh | CB18: ='14 - T6'!$G$16 | CC18: ='14 - T6'!$I$16 | CD18: ='15 - T7'!$E$16 | CE18: ='15 - T7'!$G$16 | CF18: ='15 - T7'!$I$16 | CG18: ='16 - CN'!$E$16 -> Khai Anh | CH18: ='16 - CN'!$G$16 | CI18: ='16 - CN'!$I$16 | CJ18: ='17 - T2'!$E$16 -> Khai Anh | CK18: ='17 - T2'!$G$16 | CL18: ='17 - T2'!$I$16 | CM18: ='18 - T3'!$E$16 -> Khai Anh | CN18: ='18 - T3'!$G$16 | CO18: ='18 - T3'!$I$16 | CP18: ='19 - T4'!$E$16 -> Phương Trang | CQ18: ='19 - T4'!$G$16 | CR18: ='19 - T4'!$I$16 | CS18: ='20 - T5'!$E$16 -> Khai Anh | CT18: ='20 - T5'!$G$16 | CU18: ='20 - T5'!$I$16 | CV18: ='21 - T6'!$E$16 -> Khai Anh | CW18: ='21 - T6'!$G$16 | CX18: ='21 - T6'!$I$16 | CY18: ='22 - T7'!$E$16 -> HDVL | CZ18: ='22 - T7'!$G$16 | DA18: ='22 - T7'!$I$16 | DB18: ='23 - CN'!$E$16 -> Khai Anh | DC18: ='23 - CN'!$G$16 | DD18: ='23 - CN'!$I$16 | DE18: ='24 - T2'!$E$16 -> Khai Anh | DF18: ='24 - T2'!$G$16 | DG18: ='24 - T2'!$I$16 | DH18: ='25 - T3'!$E$16 -> Thuận An | DI18: ='25 - T3'!$G$16 | DJ18: ='25 - T3'!$I$16 | DK18: ='26 - T4'!$E$16 -> Khai Anh | DL18: ='26 - T4'!$G$16 | DM18: ='26 - T4'!$I$16 | DN18: ='27 - T5'!$E$16 -> Lúa Vàng | DO18: ='27 - T5'!$G$16 | DP18: ='27 - T5'!$I$16 | DQ18: ='28 - T6'!$E$16 -> Vưu Đức Phát | DR18: ='28 - T6'!$G$16 | DS18: ='28 - T6'!$I$16 | DT18: ='29 - T7'!$E$16 -> TÀI XẾ NGHỈ | DU18: ='29 - T7'!$G$16 | DV18: ='29 - T7'!$I$16 | DW18: ='30 - CN'!$E$16 | DX18: ='30 - CN'!$G$16 | DY18: ='30 - CN'!$I$16 | DZ18: ='31 - T2'!$E$16 | EA18: ='31 - T2'!$G$16 | EB18: ='31 - T2'!$I$16
A19: 15 | B19: 63H04236 | C19: =SUM(D19:S19) -> 25 | D19: =COUNTIF($AN19:$EB19,D$2) -> 11 | E19: =COUNTIF($AN19:$EB19,E$2) -> 1 | F19: =COUNTIF($AN19:$EB19,F$2) -> 0 | G19: =COUNTIF($AN19:$EB19,G$2) -> 3 | H19: =COUNTIF($AN19:$EB19,H$2) -> 2 | I19: =COUNTIF($AN19:$EB19,I$2) -> 0 | J19: =COUNTIF($AN19:$EB19,J$2) -> 3 | K19: =COUNTIF($AN19:$EB19,K$2) -> 0 | ... S19: =COUNTIF($AN19:$EB19,S$2) -> 5 | U19: =COUNTIF($AN19:$EB19,U$2) -> 0 | V19: =COUNTIF($AN19:$EB19,V$2) -> 0 | W19: =COUNTIF($AN19:$EB19,W$2) -> 0 | X19: =COUNTIF($AN19:$EB19,X$2) -> 0 | Z19: ='01 - T7'!$N$17+'02 - CN'!$N$17+'03 - T2'!$N$17+'04 - T3'!$N$17+'05 - T4'!$N$17+'06 - T5'!$N$17+'07 - T6'!$N$17+'08 - T7'!$N$17+'09 - CN'!$N$17+'10 - T2'!$N$17+'11 - T3'!$N$17+'12 - T4'!$N$17+'13 - T5'!$N$17+'14 - T6'!$N$17+'15 - T7'!$N$17+'16 - CN'!$N$17+'17 - T2'!$N$17+'18 - T3'!$N$17+'19 - T4'!$N$17+'20 - T5'!$N$17+'21 - T6'!$N$17+'22 - T7'!$N$17+'23 - CN'!$N$17+'24 - T2'!$N$17+'25 - T3'!$N$17+'26 - T4'!$N$17+'27 - T5'!$N$17+'28 - T6'!$N$17+'29 - T7'!$N$17+'30 - CN'!$N$17+'31 - T2'!$N$17 -> 25 | AA19: =IF(B19="","",Z19/31) -> 0.80645161 | AB19: =IF(B19="","",RANK(C19,$C$5:$C$30,0)) -> 15 | AN19: ='01 - T7'!$E$17 -> HDVL | AO19: ='01 - T7'!$G$17 | AP19: ='01 - T7'!$I$17 | AQ19: ='02 - CN'!$E$17 | AR19: ='02 - CN'!$G$17 | AS19: ='02 - CN'!$I$17 | AT19: ='03 - T2'!$E$17 | AU19: ='03 - T2'!$G$17 | AV19: ='03 - T2'!$I$17 | AW19: ='04 - T3'!$E$17 | AX19: ='04 - T3'!$G$17 | AY19: ='04 - T3'!$I$17 | AZ19: ='05 - T4'!$E$17 -> Lúa Vàng | BA19: ='05 - T4'!$G$17 | BB19: ='05 - T4'!$I$17 | BC19: ='06 - T5'!$E$17 -> HDVL | BD19: ='06 - T5'!$G$17 | BE19: ='06 - T5'!$I$17 | BF19: ='07 - T6'!$E$17 -> HDVL | BG19: ='07 - T6'!$G$17 | BH19: ='07 - T6'!$I$17 | BI19: ='08 - T7'!$E$17 -> HDVL | BJ19: ='08 - T7'!$G$17 | BK19: ='08 - T7'!$I$17 | BL19: ='09 - CN'!$E$17 -> Thuận An | BM19: ='09 - CN'!$G$17 | BN19: ='09 - CN'!$I$17 | BO19: ='10 - T2'!$E$17 -> Khai Anh | BP19: ='10 - T2'!$G$17 | BQ19: ='10 - T2'!$I$17 | BR19: ='11 - T3'!$E$17 -> Khai Anh | BS19: ='11 - T3'!$G$17 | BT19: ='11 - T3'!$I$17 | BU19: ='12 - T4'!$E$17 -> Khai Anh | BV19: ='12 - T4'!$G$17 | BW19: ='12 - T4'!$I$17 | BX19: ='13 - T5'!$E$17 -> Lúa Vàng | BY19: ='13 - T5'!$G$17 | BZ19: ='13 - T5'!$I$17 | CA19: ='14 - T6'!$E$17 -> Kim Bàng | CB19: ='14 - T6'!$G$17 | CC19: ='14 - T6'!$I$17 | CD19: ='15 - T7'!$E$17 | CE19: ='15 - T7'!$G$17 | CF19: ='15 - T7'!$I$17 | CG19: ='16 - CN'!$E$17 -> Khai Anh | CH19: ='16 - CN'!$G$17 | CI19: ='16 - CN'!$I$17 | CJ19: ='17 - T2'!$E$17 -> Khai Anh | CK19: ='17 - T2'!$G$17 | CL19: ='17 - T2'!$I$17 | CM19: ='18 - T3'!$E$17 -> Phương Trang | CN19: ='18 - T3'!$G$17 | CO19: ='18 - T3'!$I$17 | CP19: ='19 - T4'!$E$17 -> Phương Trang | CQ19: ='19 - T4'!$G$17 | CR19: ='19 - T4'!$I$17 | CS19: ='20 - T5'!$E$17 -> Thuận An | CT19: ='20 - T5'!$G$17 | CU19: ='20 - T5'!$I$17 | CV19: ='21 - T6'!$E$17 -> Khai Anh | CW19: ='21 - T6'!$G$17 | CX19: ='21 - T6'!$I$17 | CY19: ='22 - T7'!$E$17 -> HDVL | CZ19: ='22 - T7'!$G$17 | DA19: ='22 - T7'!$I$17 | DB19: ='23 - CN'!$E$17 -> Khai Anh | DC19: ='23 - CN'!$G$17 | DD19: ='23 - CN'!$I$17 | DE19: ='24 - T2'!$E$17 -> Khai Anh | DF19: ='24 - T2'!$G$17 | DG19: ='24 - T2'!$I$17 | DH19: ='25 - T3'!$E$17 -> Khai Anh | DI19: ='25 - T3'!$G$17 | DJ19: ='25 - T3'!$I$17 | DK19: ='26 - T4'!$E$17 -> Phương Trang | DL19: ='26 - T4'!$G$17 | DM19: ='26 - T4'!$I$17 | DN19: ='27 - T5'!$E$17 -> Khai Anh | DO19: ='27 - T5'!$G$17 | DP19: ='27 - T5'!$I$17 | DQ19: ='28 - T6'!$E$17 -> Khai Anh | DR19: ='28 - T6'!$G$17 | DS19: ='28 - T6'!$I$17 | DT19: ='29 - T7'!$E$17 -> Thuận An | DU19: ='29 - T7'!$G$17 | DV19: ='29 - T7'!$I$17 | DW19: ='30 - CN'!$E$17 | DX19: ='30 - CN'!$G$17 | DY19: ='30 - CN'!$I$17 | DZ19: ='31 - T2'!$E$17 | EA19: ='31 - T2'!$G$17 | EB19: ='31 - T2'!$I$17
